Workbook

Sheet 版本交付阶梯图

Sheet 汇总
A1: 汇总与折算（公式驱动，唯一维护处）
A3: WBS | B3: 模块/阶段 | C3: 人日小计 | D3: 开始日期 | E3: 结束日期 | F3: 关键风险/依赖
A4: A1 | B4: 需求调研与PRD | C4: =SUMIF('功能点评估（全栈）'!$A$4:$A$76,$A4,'功能点评估（全栈）'!$H$4:$H$76) -> 6 | D4: =IF(COUNT('功能点评估（全栈）'!K4:K7)=0,"",MIN('功能点评估（全栈）'!K4:K7)) -> 46267 | E4: =IF(COUNT('功能点评估（全栈）'!L4:L7)=0,"",MAX('功能点评估（全栈）'!L4:L7)) -> 46283 | F4: #2 #3 材料未齐即启动，PRD 有返工风险
A5: A2 | B5: 原型设计 | C5: =SUMIF('功能点评估（全栈）'!$A$4:$A$76,$A5,'功能点评估（全栈）'!$H$4:$H$76) -> 1 | D5: =IF(COUNT('功能点评估（全栈）'!K8:K9)=0,"",MIN('功能点评估（全栈）'!K8:K9)) -> 46279 | E5: =IF(COUNT('功能点评估（全栈）'!L8:L9)=0,"",MAX('功能点评估（全栈）'!L8:L9)) -> 46283 | F5: v2.8 已交付，仅评修订量
A6: B0 | B6: 公共底座与移动端 | C6: =SUMIF('功能点评估（全栈）'!$A$4:$A$76,$A6,'功能点评估（全栈）'!$H$4:$H$76) -> 8.75 | D6: =IF(COUNT('功能点评估（全栈）'!K10:K15)=0,"",MIN('功能点评估（全栈）'!K10:K15)) -> 46272 | E6: =IF(COUNT('功能点评估（全栈）'!L10:L15)=0,"",MAX('功能点评估（全栈）'!L10:L15)) -> 46318
A7: B1 | B7: 基础数据 | C7: =SUMIF('功能点评估（全栈）'!$A$4:$A$76,$A7,'功能点评估（全栈）'!$H$4:$H$76) -> 9.5 | D7: =IF(COUNT('功能点评估（全栈）'!K16:K20)=0,"",MIN('功能点评估（全栈）'!K16:K20)) -> 46275 | E7: =IF(COUNT('功能点评估（全栈）'!L16:L20)=0,"",MAX('功能点评估（全栈）'!L16:L20)) -> 46316
A8: B2 | B8: 项目管理中心 | C8: =SUMIF('功能点评估（全栈）'!$A$4:$A$76,$A8,'功能点评估（全栈）'!$H$4:$H$76) -> 6.5 | D8: =IF(COUNT('功能点评估（全栈）'!K21:K25)=0,"",MIN('功能点评估（全栈）'!K21:K25)) -> 46275 | E8: =IF(COUNT('功能点评估（全栈）'!L21:L25)=0,"",MAX('功能点评估（全栈）'!L21:L25)) -> 46308
A9: B3 | B9: 仓储作业 ★核心 | C9: =SUMIF('功能点评估（全栈）'!$A$4:$A$76,$A9,'功能点评估（全栈）'!$H$4:$H$76) -> 24.5 | D9: =IF(COUNT('功能点评估（全栈）'!K26:K37)=0,"",MIN('功能点评估（全栈）'!K26:K37)) -> 46276 | E9: =IF(COUNT('功能点评估（全栈）'!L26:L37)=0,"",MAX('功能点评估（全栈）'!L26:L37)) -> 46349 | F9: 11 类单据；无组装/拆卸（BOM 结果导向·出库按组合扣减/退租按零件入库）
A10: B4 | B10: 租赁管理 | C10: =SUMIF('功能点评估（全栈）'!$A$4:$A$76,$A10,'功能点评估（全栈）'!$H$4:$H$76) -> 13 | D10: =IF(COUNT('功能点评估（全栈）'!K38:K42)=0,"",MIN('功能点评估（全栈）'!K38:K42)) -> 46307 | E10: =IF(COUNT('功能点评估（全栈）'!L38:L42)=0,"",MAX('功能点评估（全栈）'!L38:L42)) -> 46343 | F10: 计费定案（09-15·D-145）：按时间周期直录日租金／按次次单价·按持有量计租·三段式仅档案参考价
A11: B5 | B11: 销售管理 | C11: =SUMIF('功能点评估（全栈）'!$A$4:$A$76,$A11,'功能点评估（全栈）'!$H$4:$H$76) -> 10.5 | D11: =IF(COUNT('功能点评估（全栈）'!K43:K47)=0,"",MIN('功能点评估（全栈）'!K43:K47)) -> 46276 | E11: =IF(COUNT('功能点评估（全栈）'!L43:L47)=0,"",MAX('功能点评估（全栈）'!L43:L47)) -> 46350 | F11: #6 路凯对接方式待定
A12: B6 | B12: 财务协同 | C12: =SUMIF('功能点评估（全栈）'!$A$4:$A$76,$A12,'功能点评估（全栈）'!$H$4:$H$76) -> 18.5 | D12: =IF(COUNT('功能点评估（全栈）'!K48:K55)=0,"",MIN('功能点评估（全栈）'!K48:K55)) -> 46282 | E12: =IF(COUNT('功能点评估（全栈）'!L48:L55)=0,"",MAX('功能点评估（全栈）'!L48:L55)) -> 46356 | F12: #5 单据/水单样例、#8 开票主体待提供
A13: B7 | B13: 系统管理 | C13: =SUMIF('功能点评估（全栈）'!$A$4:$A$76,$A13,'功能点评估（全栈）'!$H$4:$H$76) -> 3 | D13: =IF(COUNT('功能点评估（全栈）'!K56:K58)=0,"",MIN('功能点评估（全栈）'!K56:K58)) -> 46289 | E13: =IF(COUNT('功能点评估（全栈）'!L56:L58)=0,"",MAX('功能点评估（全栈）'!L56:L58)) -> 46349
A14: B8 | B14: 采购管理 | C14: =SUMIF('功能点评估（全栈）'!$A$4:$A$76,$A14,'功能点评估（全栈）'!$H$4:$H$76) -> 7.5 | D14: =IF(COUNT('功能点评估（全栈）'!K59:K63)=0,"",MIN('功能点评估（全栈）'!K59:K63)) -> 46286 | E14: =IF(COUNT('功能点评估（全栈）'!L59:L63)=0,"",MAX('功能点评估（全栈）'!L59:L63)) -> 46295 | F14: 第 2 次会新增模块（09-04 拍板第一期闭环）
A15: C1 | B15: 测试 | C15: =SUMIF('功能点评估（全栈）'!$A$4:$A$76,$A15,'功能点评估（全栈）'!$H$4:$H$76) -> 17 | D15: =IF(COUNT('功能点评估（全栈）'!K64:K65)=0,"",MIN('功能点评估（全栈）'!K64:K65)) -> 46308 | E15: =IF(COUNT('功能点评估（全栈）'!L64:L65)=0,"",MAX('功能点评估（全栈）'!L64:L65)) -> 46370 | F15: 用例需覆盖 F01 五条主线全链路
A16: C2 | B16: 数据迁移 | C16: =SUMIF('功能点评估（全栈）'!$A$4:$A$76,$A16,'功能点评估（全栈）'!$H$4:$H$76) -> 13 | D16: =IF(COUNT('功能点评估（全栈）'!K66:K68)=0,"",MIN('功能点评估（全栈）'!K66:K68)) -> 46308 | E16: =IF(COUNT('功能点评估（全栈）'!L66:L68)=0,"",MAX('功能点评估（全栈）'!L66:L68)) -> 46367 | F16: #4 主数据清单与格式待提供
A17: C3 | B17: 上线部署 | C17: =SUMIF('功能点评估（全栈）'!$A$4:$A$76,$A17,'功能点评估（全栈）'!$H$4:$H$76) -> 15 | D17: =IF(COUNT('功能点评估（全栈）'!K69:K71)=0,"",MIN('功能点评估（全栈）'!K69:K71)) -> 46314 | E17: =IF(COUNT('功能点评估（全栈）'!L69:L71)=0,"",MAX('功能点评估（全栈）'!L69:L71)) -> 46381 | F17: 试运行窗口待与客户确认
B18: 合计 / 全跨度 | C18: =SUM(C4:C17) -> 153.75 | D18: =IF(COUNT(D4:D17)=0,"",MIN(D4:D17)) -> 46267 | E18: =IF(COUNT(E4:E17)=0,"",MAX(E4:E17)) -> 46381
A20: 版本里程碑（人日 × 上线节点 × 范围，合并原「版本小计 + 里程碑一览」）
A21: 版本 | B21: 上线 / 完成节点 | C21: 范围与业务 | D21: 人日小计 | E21: 含缓冲 | F21: 开始日期 | G21: 结束日期 | H21: 无AI对照 （方案1·约219人日）
A22: 前置 | B22: 09-02 ~ 09-18 定版 | C22: 需求 09-02 起（第 2~4 次沟通＋09-15 拍板包）+ 计费定案（按天计租）+ PRD 冻结 + 芋道底座/编码规范 | D22: 12.75 | E22: =ROUND(D22*(1+$C$46),2) -> 14.66 | F22: 46267 | G22: 46283 | H22: 无AI 09-23
A23: V1.0 | B23: ★ 10-20 上线（09-15 增补·初估） | C23: 买卖版：买卖全链 + 库存（查询五态/调拨/其他出入库）+ 应收六来源/回款 + 权限矩阵；+库存事件流水/采购退货/销售退货（09-15 增·人日待评估） | D23: 41 | E23: =ROUND(D23*(1+$C$46),2) -> 47.15 | F23: 46275 | G23: 46295 | H23: 无AI 11-03
A24: V1.1 | B24: ★ 11-24 上线（初估） | C24: 租赁版：租赁循环（租赁单/租赁出库/退租入库两事件）+ BOM + 按天计租（直录日租金） + 应付/付款 + 移动端 H5；+转移出库/按持有量计租/退款登记（09-15 增·人日待评估） | D24: 34.5 | E24: =ROUND(D24*(1+$C$46),2) -> 39.68 | F24: 46282 | G24: 46338 | H24: 无AI 12-17
A25: V2.0 | B25: ★ 12-14 上线（初估） | C25: 深化版：租入三单（L3/L4）+ 路凯对接 + 财务收口（开票/银行回单核销/财务看板）+ 数据字典 | D25: 20.5 | E25: =ROUND(D25*(1+$C$46),2) -> 23.58 | F25: 46339 | G25: 46356 | H25: 无AI 01-22
A26: 验收收口 | B26: 01-08 前后（初估） | C26: 试运行 2 周（真实订单并行）+ 01-08 前验收；富余产能启动 2027 backlog | H26: 无AI 2027-02-05
A27: 各版 | B27: 10-13 / 11-16 / 12-08 启动（初估） | C27: 测试 / UAT / 数据迁移 / 部署 / 切换 / 试运行——每版上线前各跑一轮（单轮 15 人日×3） | D27: 45 | E27: =ROUND(D27*(1+$C$46),2) -> 51.75 | F27: 46308 | G27: 46381 | H27: —
C28: 版本人日合计（校验=总合计 C18） | D28: =SUM(D22:D27) -> 153.75 | E28: =IF(D28=C18,"✓ 一致","✗ 不一致") -> ✓ 一致
A30: 按月负载（原「按月版本规划」主体并入）
A31: 月份 | B31: 计划人日 （含缓冲） | C31: 当月产能 （人日） | D31: 负载率 | E31: 当月里程碑与内容摘要
A32: 2026-09 | B32: 46 | C32: 54 | D32: =B32/C32 -> 0.85185185 | E32: 需求 09-18 冻结；底座+V1.0 全量开发（09-15 起）＋采购/销售退货单与库存事件流水并入
A33: 2026-10 | B33: 47.5 | C33: 48 | D33: =B33/C33 -> 0.98958333 | E33: 10-13~20 轮1：集成测试/UAT/主数据迁移/部署；★10-20 V1.0 上线（09-15 增补口径·初估）
A34: 2026-11 | B34: 46 | C34: 63 | D34: =B34/C34 -> 0.73015873 | E34: V1.1 开发完成（含移动端 H5＋转移出库＋按天计租引擎＋退款登记）；11-16~23 轮2；★11-24 V1.1 上线
A35: 2026-12 | B35: 37.31 | C35: 69 | D35: =B35/C35 -> 0.54072464 | E35: 12-08~11 轮3（租入在途迁移/部署）；★12-14 V2.0 全量上线（128+ 页口径）；01-08 前验收
A36: 合计 | B36: =SUM(B32:B35) -> 176.81 | C36: =SUM(C32:C35) -> 234 | D36: =B36/C36 -> 0.75559829
A38: AI 协作（Claude Code）前提与风险
A39: R1 评审带宽 | B39: AI 产出量大，3 名工程师须固定每日代码评审时段消化
A40: R2 风格统一 | B40: 底座周（09-09~10）必须落编码规范与组件约定，统一三套 AI 风格
A41: R3 关键逻辑 | B41: 库存过账/组装拆卸/四态计费/水单核销以人工设计主导，勿盲信 AI 产出
A42: R4 磨合回退 | B42: 若 AI 协作磨合不顺（提速退化），工期按 约 219 人日口径上浮，里程碑顺延
A43: R5 外部依赖 | B43: #6 路凯对接方式、#5 水单样例、#8 开票主体——未定项集中在 V2.0 前必须落实
A45: 参数与折算
...

Sheet 甘特图-功能点级
A1: 甘特图 · WBS × 版本（23 行概览·0915 增补）
A2: 口径：横轴 78 个工作日（09-02~12-25·周末与国庆不排）；09-15 增补口径 153.75 人日·节点 10-20/11-24/12-14（初估·开发重估后刷新）
A3: WBS | B3: 模块 / 内容 | C3: 人日 | D3: 开始 | E3: 结束 | F3: 9月 | AA3: 10月 | AR3: 11月 | BM3: 12月
F4: 46267 | G4: 46268 | H4: 46269 | I4: 46272 | J4: 46273 | K4: 46274 | L4: 46275 | M4: 46276 | N4: 46279 | O4: 46280 | P4: 46281 | Q4: 46282 | R4: 46283 | S4: 46286 | T4: 46287 | U4: 46288 | V4: 46289 | W4: 46290 | X4: 46293 | Y4: 46294 | Z4: 46295 | AA4: 46303 | AB4: 46304 | AC4: 46307 | AD4: 46308 | AE4: 46309 | AF4: 46310 | AG4: 46311 | AH4: 46314 | AI4: 46315 | AJ4: 46316 | AK4: 46317 | AL4: 46318 | AM4: 46321 | AN4: 46322 | AO4: 46323 | AP4: 46324 | AQ4: 46325 | AR4: 46328 | AS4: 46329 | AT4: 46330 | AU4: 46331 | AV4: 46332 | AW4: 46335 | AX4: 46336 | AY4: 46337 | AZ4: 46338 | BA4: 46339 | BB4: 46342 | BC4: 46343 | BD4: 46344 | BE4: 46345 | BF4: 46346 | BG4: 46349 | BH4: 46350 | BI4: 46351 | BJ4: 46352 | BK4: 46353 | BL4: 46356 | BM4: 46357 | BN4: 46358 | BO4: 46359 | BP4: 46360 | BQ4: 46363 | BR4: 46364 | BS4: 46365 | BT4: 46366 | BU4: 46367 | BV4: 46370 | BW4: 46371 | BX4: 46372 | BY4: 46373 | BZ4: 46374 | CA4: 46377 | CB4: 46378 | CC4: 46379 | CD4: 46380 | CE4: 46381
A5: 前置（09-02 ~ 09-18 · 需求+原型+底座）
A6: 前置 | B6: 需求调研与 PRD（四轮走查+计费定案 09-15+评审冻结·09-18） | C6: 6 | D6: 46267 | E6: 46283
A7: 前置 | B7: 原型改造与定稿（G31~G39·128+ HTML·09-18 定稿） | C7: 1 | D7: 46279 | E7: 46283
A8: 前置 | B8: 公共底座（脚手架/登录页+登录态/通用组件） | C8: 5.75 | D8: 46272 | E8: 46275
A9: V1.0 买卖版 ★ 10-20 上线
A10: V1.0 | B10: 基础数据（项目/客商/产品档案[两档合并]/库位） | C10: 6.5 | D10: 46275 | E10: 46283
A11: V1.0 | B11: 项目域（编码规则 + 上下游 M:N 绑定） | C11: 1.5 | D11: 46275 | E11: 46276
A12: V1.0 | B12: 仓储 V1.0（采购入库/库存查询五态/销售出库/其他出入库/调拨/库存事件流水） | C12: 14 | D12: 46276 | E12: 46293
A13: V1.0 | B13: 销售订单（代下单+审核+附件/关闭+销售退货单） | C13: 4.5 | D13: 46276 | E13: 46289
A14: V1.0 | B14: 财务（应收六来源含按天期段化 + 回款） | C14: 5 | D14: 46282 | E14: 46288
A15: V1.0 | B15: 系统权限（6 角色·矩阵 19 类） | C15: 1.5 | D15: 46289 | E15: 46290
A16: V1.0 | B16: 采购域（订单/审核/入库发起/买卖线/采购退货单）+ 站内信 | C16: 8 | D16: 46286 | E16: 46295
A17: V1.1 租赁版（含移动端 H5）★ 11-24 上线
A18: V1.1 | B18: BOM 维护（版本 + 配比校验·结果导向） | C18: 3 | D18: 46314 | E18: 46316
A19: V1.1 | B19: 看板 / 详情 / 我的待办（19 类） | C19: 5 | D19: 46290 | E19: 46308
A20: V1.1 | B20: 仓储租赁循环（租赁出库/退租入库两事件/盘点） | C20: 7.5 | D20: 46309 | E20: 46325
A21: V1.1 | B21: 计费（直录日租金）+ 租赁单 + 转移出库 + 持有量计租引擎 | C21: 11 | D21: 46307 | E21: 46328
A22: V1.1 | B22: 应付五来源（租入对称按天计租）+ 付款登记 + 退款登记 | C22: 6 | D22: 46282 | E22: 46330
A23: V1.1 | B23: 移动端 H5 五页（企微·审批 P0） | C23: 2.5 | D23: 46314 | E23: 46318
A24: V2.0 深化版 ★ 12-14 上线
A25: V2.0 | B25: 租入三单（租入单/租入入库/租入归还） | C25: 5 | D25: 46339 | E25: 46349
A26: V2.0 | B26: 路凯订单同步 + 结算导出 | C26: 6 | D26: 46342 | E26: 46350
A27: V2.0 | B27: 财务收口（开票/银行回单核销/财务看板） | C27: 8 | D27: 46344 | E27: 46356
A28: V2.0 | B28: 操作日志 + 数据字典（28 组 141 项·物料类型 10 值） | C28: 1.5 | D28: 46346 | E28: 46349
A29: 各版支撑（测试 / 迁移 / 上线 · 每版一轮）
A30: 各版 | B30: 集成测试 / UAT（F01 七泳道·轮 10-13/11-16/12-08） | C30: 17 | D30: 46308 | E30: 46370
A31: 各版 | B31: 数据迁移（主数据/期初五态导库/核对） | C31: 13 | D31: 46308 | E31: 46367
A32: 各版 | B32: 部署 / 切换 / 试运行 | C32: 15 | D32: 46314 | E32: 46381

Sheet 甘特图-任务级
A1: 甘特图 · 任务级（68 行全量·0915 增补）
A2: 口径：横轴 78 个工作日（09-02~12-25·周末与国庆不排）；09-15 增补口径 153.75 人日·节点 10-20/11-24/12-14（初估·开发重估后刷新）
A3: WBS | B3: 功能点 | C3: 任务 | D3: 版本 | E3: 人日 | F3: 开始 | G3: 结束 | H3: 9月 | AC3: 10月 | AT3: 11月 | BO3: 12月
H4: 46267 | I4: 46268 | J4: 46269 | K4: 46272 | L4: 46273 | M4: 46274 | N4: 46275 | O4: 46276 | P4: 46279 | Q4: 46280 | R4: 46281 | S4: 46282 | T4: 46283 | U4: 46286 | V4: 46287 | W4: 46288 | X4: 46289 | Y4: 46290 | Z4: 46293 | AA4: 46294 | AB4: 46295 | AC4: 46303 | AD4: 46304 | AE4: 46307 | AF4: 46308 | AG4: 46309 | AH4: 46310 | AI4: 46311 | AJ4: 46314 | AK4: 46315 | AL4: 46316 | AM4: 46317 | AN4: 46318 | AO4: 46321 | AP4: 46322 | AQ4: 46323 | AR4: 46324 | AS4: 46325 | AT4: 46328 | AU4: 46329 | AV4: 46330 | AW4: 46331 | AX4: 46332 | AY4: 46335 | AZ4: 46336 | BA4: 46337 | BB4: 46338 | BC4: 46339 | BD4: 46342 | BE4: 46343 | BF4: 46344 | BG4: 46345 | BH4: 46346 | BI4: 46349 | BJ4: 46350 | BK4: 46351 | BL4: 46352 | BM4: 46353 | BN4: 46356 | BO4: 46357 | BP4: 46358 | BQ4: 46359 | BR4: 46360 | BS4: 46363 | BT4: 46364 | BU4: 46365 | BV4: 46366 | BW4: 46367 | BX4: 46370 | BY4: 46371 | BZ4: 46372 | CA4: 46373 | CB4: 46374 | CC4: 46377 | CD4: 46378 | CE4: 46379 | CF4: 46380 | CG4: 46381
A5: 前置（09-02 ~ 09-18 · 需求+原型+底座）
A6: A1 | B6: — | C6: 原型走查与字段确认（四轮评审至第 3 次沟通·115 页口径） | D6: 前置 | E6: 1.5 | F6: 46267 | G6: 46279
A7: A1 | B7: — | C7: 计费规则与单据流程确认（三段式计费 09-11 拍板定版） | D7: 前置 | E7: 2 | F7: 46274 | G7: 46280
A8: A1 | B8: — | C8: PRD 编写（P2-R01 V1.0·10 模块 UC89/AC55） | D8: 前置 | E8: 1.5 | F8: 46274 | G8: 46275
A9: A1 | B9: — | C9: PRD 评审与范围冻结 | D9: 前置 | E9: 1 | F9: 46276 | G9: 46283
A10: A2 | B10: — | C10: 原型按评审反馈修订 | D10: 前置 | E10: 0.5 | F10: 46279 | G10: 46283
A11: A2 | B11: — | C11: 原型评审确认与定稿 | D11: 前置 | E11: 0.5 | F11: 46283 | G11: 46283
A12: B0 | B12: — | C12: 工程脚手架与 CI/CD | D12: 前置 | E12: 1.5 | F12: 46272 | G12: 46273
A13: B0 | B13: — | C13: 登录页+默认登录态+框架权限（企微扫码·退出键域） | D13: 前置 | E13: 0.75 | F13: 46274 | G13: 46274
A14: B0 | B14: — | C14: 通用组件（单据/列表/导入导出/弹窗/四段式详情双列） | D14: 前置 | E14: 3.5 | F14: 46274 | G14: 46275
A15: V1.0 买卖版 ★ 10-20 上线（09-15 增补·初估）
A16: B0 | B16: — | C16: 站内信（顶栏通知铃铛·四类消息·已读键域） | D16: V1.0 | E16: 0.5 | F16: 46293 | G16: 46293
A17: B1 | B17: FP1-01 | C17: 项目档案：页面 + 表结构与接口 | D17: V1.0 | E17: 1.5 | F17: 46275 | G17: 46276
A18: B1 | B18: FP1-02 | C18: 客商管理：客户/供应商/客商兼供应商（含开票资料） | D18: V1.0 | E18: 2 | F18: 46279 | G18: 46280
A19: B1 | B19: FP1-03 | C19: 产品档案：物料类型×分类两级+四参考价+供应商税率+三段式租价（器具/零部件两档案已合并） | D19: V1.0 | E19: 2 | F19: 46281 | G19: 46282
A20: B1 | B20: FP1-06 | C20: 库位档案：仓/区/位三级 + XNC 客户虚拟仓 | D20: V1.0 | E20: 1 | F20: 46283 | G20: 46283
A21: B2 | B21: FP2-01 | C21: 项目编码规则：规则引擎 + 配置 | D21: V1.0 | E21: 0.5 | F21: 46275 | G21: 46275
A22: B2 | B22: FP2-02 | C22: 上下游绑定：多对多关系维护 | D22: V1.0 | E22: 1 | F22: 46276 | G22: 46276
A23: B3 | B23: FP3-01 | C23: 采购入库单（执行）：录单 + 入库过账与库存更新 | D23: V1.0 | E23: 2 | F23: 46276 | G23: 46279
A24: B3 | B24: FP3-06 | C24: 库存查询：五态 + 组合视图 + 客户在租下钻 + 资产轨迹 + 租入态筛选 | D24: V1.0 | E24: 3 | F24: 46280 | G24: 46281
A25: B3 | B25: （待补） | C25: 销售出库单：录单 + 出库过账（买卖线） | D25: V1.0 | E25: 2 | F25: 46282 | G25: 46283
A26: B3 | B26: （待补） | C26: 其他入库单：盘盈/退货/其他（期初走数据迁移导库·无期初入口） | D26: V1.0 | E26: 1.5 | F26: 46286 | G26: 46287
A27: B3 | B27: （待补） | C27: 其他出库单：报废/盘亏/赔偿核销/其他 | D27: V1.0 | E27: 1.5 | F27: 46288 | G27: 46289
... A37: B8 | B37: FP8-02 | C37: 采购订单审核：状态流 | D37: V1.0 | E37: 1 | F37: 46288 | G37: 46288
A38: B8
A39: B8 | B39: FP8-04 | C39: 销售订单（买卖线）：客户购买订单 | D39: V1.0 | E39: 1.5 | F39: 46293 | G39: 46294
A40: B8 | B40: （待补） | C40: 采购退货单：收货拒收/入库后退货·可退上限·关联采购入库 | D40: V1.0 | E40: 1.5 | F40: 46294 | G40: 46295
A41: V1.1 租赁版（含移动端 H5）★ 11-24 上线（初估）
A42: B0 | B42: — | C42: 移动端 H5 五页（登录/待办审批/审批详情/库存查询/我的·企微） | D42: V1.1 | E42: 2.5 | F42: 46314 | G42: 46318
A43: B0 | B43: （待补） | C43: 企微/飞书组织架构同步（部门/人员/账号映射·D-120） | D43: V1.1
A44: B1 | B44: FP1-05 | C44: 子母件 BOM：维护页 + 版本管理与配比校验 | D44: V1.1 | E44: 3 | F44: 46314 | G44: 46316
A45: B2 | B45: FP2-03 | C45: 项目看板：图表页 + 统计接口 | D45: V1.1 | E45: 1.5 | F45: 46290 | G45: 46293
A46: B2 | B46: FP2-04 | C46: 明细查看：从汇总数据进入单据明细 | D46: V1.1 | E46: 1.5 | F46: 46294 | G46: 46295
A47: B2 | B47: （待补） | C47: 我的待办：16 类待办聚合入口 | D47: V1.1 | E47: 2 | F47: 46304 | G47: 46308
A48: B3 | B48: FP3-03 | C48: 租赁出库单：录单 + 审核 + 退回对比 | D48: V1.1 | E48: 2 | F48: 46321 | G48: 46322
A49: B3 | B49: FP3-04 | C49: 退租入库单：客户退租统一入口·按零件入库·完好分流（自有回库/租入归还） | D49: V1.1 | E49: 2.5 | F49: 46323 | G49: 46325
...

Sheet 功能点评估（全栈）
A1: P1-R03 工期评估表 · 功能点级（全栈口径）
A2: 口径：人日含概要设计+编码+自测；每功能点一行、不分前后端（类型=全栈）。2026-09-05 按方案二（买卖先行）标定「版本」列：V1.0 买卖版 21 页 / V1.1 租赁版 +16 页 / V2.0 深化版 +8 页，前置=调研+底座、各版=测试迁移上线每版重复投入。标（待补）的 10 行为原型已有但 §5.1 未编 FP 码的页面。人日/评估人/开始/结束全部留白，由道远与开发逐行填写；上一版估算归档于 99-归档/P1-R03-工期评估表-20260905.xlsx。｜2026-09-06 更新：按 3 名全栈开发、2026-09-07~09-10 芋道（yudao）JDK21 底座搭建、09-10 起业务开发、原型基本确定（前置压缩）口径填入人日初评；「各版」行 H=单轮人日×3 版；评估人/起止列留白待道远与开发复核微调。｜2026-09-06 二次调整：为赶 V1.0 于 2026-10-30 上线，盘点单（FP3-05）/项目看板（FP2-03）/项目详情（FP2-04）共 8.5 人日移至 V1.1——V1.0 缩为 17 页、V1.1 扩为 +20 页，总人日不变。｜2026-09-06 方案 2.0：3 名全栈全部借助 Claude Code vibe coding，按净提速口径重估——列表/弹窗/文档类×0.6、录单+过账×0.7、复杂业务逻辑（库存过账/组装拆卸/计费/核销/路凯对接）×0.75~0.85（人工设计主导）、调研评审不提速；整体 212→149 人日（-29.6%），15% 缓冲与版本范围不变。｜I 列「含缓冲人日」=H×(1+汇总!C30) 自动计算，与「按月版本规划」口径统一（171.35），汇报用 I 列。｜2026-09-15 增补：需求期 09-02~09-18；新增功能点 6 行（转移出库/库存事件流水/按持有量计租/采购退货/销售退货/退款登记·G33/G37/G39）＋既有行口径刷新；新行人日按 0906 口径产品侧初估（+12.5 人日·开发重估后滚动刷新）
A3: WBS | B3: 模块/阶段 | C3: 功能点 | D3: 任务 | E3: 类型 | F3: 对应原型页面 | G3: 版本 | H3: 人日 | I3: 含缓冲人日 （=人日×1.15） | J3: 评估人 | K3: 开始时间 | L3: 结束时间 | M3: 备注（风险/依赖）
A4: A1 | B4: 需求调研与PRD | C4: — | D4: 原型走查与字段确认（四轮评审·第 2~4 次沟通 09-02~09-14） | E4: 调研 | F4: 全量 | G4: 前置 | H4: 1.5 | I4: =H4*(1+汇总!$C$46) -> 1.725 | J4: 吕道远 | K4: 46267 | L4: 46279 | M4: ✅ 已完成（09-02 第 2 次沟通起·09-14 第 4 次沟通收口）；依赖 #2 #3：账号或全套截图；走查结论直接落到 PRD
A5: A1 | B5: 需求调研与PRD | C5: — | D5: 计费规则与单据流程确认（09-11 三段式→09-15 改定：按时间周期直录日租金/按次次单价·按持有量计租） | E5: 调研 | F5: — | G5: 前置 | H5: 2 | I5: =H5*(1+汇总!$C$46) -> 2.3 | J5: 吕道远 | K5: 46274 | L5: 46280 | M5: ✅ 已定案（09-15·D-145；「无日租金」口径由 G39 修订）；依赖 #1 #5：合同/报价单、单据样例
A6: A1 | B6: 需求调研与PRD | C6: — | D6: PRD 编写（P2-R01 V1.0·10 模块 UC89/AC55） | E6: 文档 | F6: 全量 | G6: 前置 | H6: 1.5 | I6: =H6*(1+汇总!$C$46) -> 1.725 | J6: 吕道远 | K6: 46274 | L6: 46275 | M6: ✅ 已完成（09-12 定版·现 V1.1+附录 A 台账）
A7: A1 | B7: 需求调研与PRD | C7: — | D7: PRD 评审与范围冻结 | E7: 文档 | F7: 全量 | G7: 前置 | H7: 1 | I7: =H7*(1+汇总!$C$46) -> 1.15 | J7: 吕道远 | K7: 46276 | L7: 46283 | M7: ⏳ 09-18（本周五）范围冻结（拍板台账滚动至 09-15·D-145 待归并）；客户确认后冻结范围，原型同步定稿
A8: A2 | B8: 原型设计 | C8: — | D8: 原型按评审反馈修订 | E8: 原型 | F8: 涉及页视反馈 | G8: 前置 | H8: 0.5 | I8: =H8*(1+汇总!$C$46) -> 0.575 | J8: 吕道远 | K8: 46279 | L8: 46283 | M8: G31~G39 改造包进行中（弹窗页面化/转移出库/字段口径/按天计租）·09-18 定稿；v2.8 已交付，仅评修订量
A9: A2 | B9: 原型设计 | C9: — | D9: 原型评审确认与定稿 | E9: 原型 | F9: 全量 + F01 | G9: 前置 | H9: 0.5 | I9: =H9*(1+汇总!$C$46) -> 0.575 | J9: 吕道远 | K9: 46283 | L9: 46283 | M9: ⏳ 09-18（本周五）定稿收口（需求期 09-02~09-18·吕道远）；与 PRD 冻结同节点收口
A10: B0 | B10: 公共底座与移动端 | C10: — | D10: 工程脚手架与 CI/CD | E10: 全栈 | F10: — | G10: 前置 | H10: 1.5 | I10: =H10*(1+汇总!$C$46) -> 1.725 | J10: 徐蔚 | K10: 46272 | L10: 46273 | M10: 本表新增项，非 P1-R01 功能点，评估时确认保留
A11: B0 | B11: 公共底座与移动端 | C11: — | D11: 登录页+默认登录态+框架权限（企微扫码·退出键域） | E11: 全栈 | F11: 登录.html+pc-auth | G11: 前置 | H11: 0.75 | I11: =H11*(1+汇总!$C$46) -> 0.8625 | J11: 徐蔚 | K11: 46274 | L11: 46274 | M11: 原型已含登录页（G19b）·客户/供应商账号不做（D-89）；原型未含登录页，按通用方案实现
A12: B0 | B12: 公共底座与移动端 | C12: — | D12: 通用组件（单据/列表/导入导出/弹窗/四段式详情双列） | E12: 全栈 | F12: 全站 69 弹窗模板 | G12: 前置 | H12: 3.5 | I12: =H12*(1+汇总!$C$46) -> 4.025 | J12: 徐蔚 | K12: 46274 | L12: 46275 | M12: 四段式详情双列化已定版（D-92·1080px）；复刻原型交互；79 个弹窗模板与四段式详情组件可直接参照
A13: B0 | B13: 公共底座与移动端 | C13: — | D13: 站内信（顶栏通知铃铛·四类消息·已读键域） | E13: 全栈 | F13: 38 业务页挂载 | G13: V1.0 | H13: 0.5 | I13: =H13*(1+汇总!$C$46) -> 0.575 | J13: 徐蔚 | K13: 46293 | L13: 46293 | M13: 账单到期/分期付款/押金应退/续租跟进（D-85）
A14: B0 | B14: 公共底座与移动端 | C14: — | D14: 移动端 H5 五页（登录/待办审批/审批详情/库存查询/我的·企微） | E14: 全栈 | F14: mobile/ 五页 | G14: V1.1 | H14: 2.5 | I14: =H14*(1+汇总!$C$46) -> 2.875 | J14: 徐蔚 | K14: 46314 | L14: 46318 | M14: 移动端审批=P0（D-86）；免二次登录
A15: B0 | B15: 公共底座与移动端 | C15: （待补） | D15: 企微/飞书组织架构同步：部门与人员同步＋账号映射（D-120 刚性需求·接口成熟） | E15: 全栈 | F15: 后台通道（无独立页） | G15: V1.1 | I15: =H15*(1+汇总!$C$46) -> 0 | J15: 徐蔚 | M15: D-120（第4次沟通 1:06:39 王琳总·拍板需工期评估）；人日待开发评估
A16: B1 | B16: 基础数据 | C16: FP1-01 | D16: 项目档案：页面 + 表结构与接口 | E16: 全栈 | F16: 项目档案 | G16: V1.0 | H16: 1.5 | I16: =H16*(1+汇总!$C$46) -> 1.725 | J16: 徐蔚 | K16: 46275 | L16: 46276
A17: B1 | B17: 基础数据 | C17: FP1-02 | D17: 客商管理：客户/供应商/客商兼供应商（含开票资料） | E17: 全栈 | F17: 客商管理 | G17: V1.0 | H17: 2 | I17: =H17*(1+汇总!$C$46) -> 2.3 | J17: 徐蔚 | K17: 46279 | L17: 46280
A18: B1 | B18: 基础数据 | C18: FP1-03 | D18: 产品档案：物料类型一级 10 值（WB/T 1058 行业口径·D-96/G38）+四参考价按物料类型通用+供应商税率+三段式仅参考价（D-145） | E18: 全栈 | F18: 产品档案（菜单名=物料档案） | G18: V1.0 | H18: 2 | I18: =H18*(1+汇总!$C$46) -> 2.3 | J18: 徐蔚 | K18: 46281 | L18: 46282 | M18: 两档案合并+productTaxes 税率行编辑器（D-03/归属权已退场）；配比错误需拦截；BOM 仅租赁域使用，随租赁版上线
A19: B1 | B19: 基础数据 | C19: FP1-05 | D19: 子母件 BOM：维护页 + 版本管理与配比校验 | E19: 全栈 | F19: BOM + BOM维护（2页） | G19: V1.1 | H19: 3 | I19: =H19*(1+汇总!$C$46) -> 3.45 | J19: 徐蔚 | K19: 46314 | L19: 46316 | M19: BOM 结果导向：出库按组合扣减，无组装过程；预留扫码接口（REQ-20）
A20: B1 | B20: 基础数据 | C20: FP1-06 | D20: 库位档案：仓库→库位两级（区层已删·G31）·客户虚拟仓不维护（D-006） | E20: 全栈 | F20: 库位档案 | G20: V1.0 | H20: 1 | I20: =H20*(1+汇总!$C$46) -> 1.15 | J20: 徐蔚 | K20: 46283 | L20: 46283 | M20: 预留扫码接口（REQ-20）
A21: B2 | B21: 项目管理中心 | C21: FP2-01 | D21: 项目编码规则：规则引擎 + 配置 | E21: 全栈 | F21: 项目档案（编码规则弹窗） | G21: V1.0 | H21: 0.5 | I21: =H21*(1+汇总!$C$46) -> 0.575 | J21: 徐蔚 | K21: 46275 | L21: 46275
A22: B2 | B22: 项目管理中心 | C22: FP2-02 | D22: 上下游绑定：多对多关系维护 | E22: 全栈 | F22: 项目档案（上下游绑定弹窗） | G22: V1.0 | H22: 1 | I22: =H22*(1+汇总!$C$46) -> 1.15 | J22: 徐蔚 | K22: 46276 | L22: 46276 | M22: M:N 多对多（G13 注记口径）；V1.0→V1.1（2026-09-06 赶 10 月上线范围调整）
A23: B2 | B23: 项目管理中心 | C23: FP2-03 | D23: 项目看板：图表页 + 统计接口 | E23: 全栈 | F23: 首页·项目看板 | G23: V1.1 | H23: 1.5 | I23: =H23*(1+汇总!$C$46) -> 1.725 | J23: 徐蔚 | K23: 46290 | L23: 46293 | M23: V1.0→V1.1（2026-09-06 赶 10 月上线范围调整）
A24: B2 | B24: 项目管理中心 | C24: FP2-04 | D24: 明细查看：从汇总数据进入单据明细 | E24: 全栈 | F24: 项目详情 | G24: V1.1 | H24: 1.5 | I24: =H24*(1+汇总!$C$46) -> 1.725 | J24: 徐蔚 | K24: 46294 | L24: 46295 | M24: FP 码待补（§5.1 未编）；聚合各模块待办，单据类型齐了才有意义，随租赁版
A25: B2 | B25: 项目管理中心 | C25: （待补） | D25: 我的待办：19 类待办聚合入口 | E25: 全栈 | F25: 我的待办 | G25: V1.1 | H25: 2 | I25: =H25*(1+汇总!$C$46) -> 2.3 | J25: 徐蔚 | K25: 46304 | L25: 46308 | M25: 19 类=可审矩阵 19 项同值源（G33 扩）；审核人筛选；V1.0 无采购订单时先手工入库，V1.0 内衔接 FP8-03 凭单发起
A26: B3 | B26: 仓储作业 ★核心 | C26: FP3-01 | D26: 采购入库单（执行）：录单 + 入库过账与库存更新 | E26: 全栈 | F26: 采购入库 列表+录单（2页） | G26: V1.0 | H26: 2 | I26: =H26*(1+汇总!$C$46) -> 2.3 | J26: 徐蔚 | K26: 46276 | L26: 46279 | M26: 凭采购订单验收；入库计量以物料基本单位（托层删·G38）；BOM 结果导向·出库按组合扣减
A27: B3 | B27: 仓储作业 ★核心 | C27: FP3-03 | D27: 租赁出库单：录单 + 审核 + 退回对比 | E27: 全栈 | F27: 租赁出库 列表+录单（2页） | G27: V1.1 | H27: 2 | I27: =H27*(1+汇总!$C$46) -> 2.3 | J27: 徐蔚 | K27: 46321 | L27: 46322 | M27: 原「组合出库」G22 统一称呼；出库确认→审核；含出货单打印页（D-144·打印模板+取数）
A28: B3 | B28: 仓储作业 ★核心 | C28: FP3-04 | D28: 退租入库单：客户退租统一入口·按零件入库·完好分流（自有回库/租入归还） | E28: 全栈 | F28: 退租入库列表+新建弹窗 | G28: V1.1 | H28: 2.5 | I28: =H28*(1+汇总!$C$46) -> 2.875 | J28: 徐蔚 | K28: 46323 | L28: 46325 | M28: 退租两事件模型（D-72）；退租申请模块已删；由退租申请（B4）触发；退租入库加拆散去向（v2.8）
A29: B3 | B29: 仓储作业 ★核心 | C29: FP3-05 | D29: 盘点单：零件/组合双口径 + 盘盈亏过账 | E29: 全栈 | F29: 盘点 列表+录入（2页） | G29: V1.1 | H29: 3 | I29: =H29*(1+汇总!$C$46) -> 3.45 | J29: 徐蔚 | K29: 46309 | L29: 46311 | M29: V1.0→V1.1（2026-09-06 赶 10 月上线范围调整）
A30: B3 | B30: 仓储作业 ★核心 | C30: FP3-06 | D30: 库存查询：五态 + 组合视图 + 客户在租下钻 + 资产轨迹 + 租入态筛选 | E30: 全栈 | F30: 库存查询 | G30: V1.0 | H30: 3 | I30: =H30*(1+汇总!$C$46) -> 3.45 | J30: 徐蔚 | K30: 46280 | L30: 46281 | M30: 在租台账已并入（G07）；租入态 D-80
A31: B3 | B31: 仓储作业 ★核心 | C31: （待补） | D31: 销售出库单：录单 + 出库过账（买卖线） | E31: 全栈 | F31: 销售出库列表 | G31: V1.0 | H31: 2 | I31: =H31*(1+汇总!$C$46) -> 2.3 | J31: 徐蔚 | K31: 46282 | L31: 46283 | M31: FP 码待补；买卖线核心出库单
A32: B3 | B32: 仓储作业 ★核心 | C32: （待补） | D32: 其他入库单：盘盈/退货/其他（期初走数据迁移导库·无期初入口） | E32: 全栈 | F32: 其他入库列表 | G32: V1.0 | H32: 1.5 | I32: =H32*(1+汇总!$C$46) -> 1.725 | J32: 徐蔚 | K32: 46286 | L32: 46287 | M32: 期初不做（D-77）；FP 码待补
A33: B3 | B33: 仓储作业 ★核心 | C33: （待补） | D33: 其他出库单：报废/盘亏/赔偿核销/其他 | E33: 全栈 | F33: 其他出库列表 | G33: V1.0 | H33: 1.5 | I33: =H33*(1+汇总!$C$46) -> 1.725 | J33: 徐蔚 | K33: 46288 | L33: 46289 | M33: FP 码待补
... A59: B8 | B59: 采购管理 | C59: FP8-01 | D59: 采购订单：新建 + 列表（独立采购线·不以销定采） | E59: 全栈 | F59: 采购订单列表 | G59: V1.0 | H59: 2 | I59: =H59*(1+汇总!$C$46) -> 2.3 | J59: 徐蔚 | K59: 46286 | L59: 46287 | M59: REQ-21
A60: B8 | B60: 采购管理 | C60: FP8-02 | D60: 采购订单审核：状态流 | E60: 全栈 | F60: 采购订单审核弹窗 | G60: V1.0 | H60: 1 | I60: =H60*(1+汇总!$C$46) -> 1.15 | J60: 徐蔚 | K60: 46288 | L60: 46288
A61: B8 | B61: 采购管理 | C61: FP8-03 | D61: 采购入库（发起）：到货登记关联采购订单 | E61: 全栈 | F61: 采购入库列表 | G61: V1.0 | H61: 1.5 | I61: =H61*(1+汇总!$C$46) -> 1.725 | J61: 徐蔚 | K61: 46289 | L61: 46290 | M61: 执行由 FP3-01 承接
A62: B8 | B62: 采购管理 | C62: FP8-04 | D62: 销售订单（买卖线）：客户购买订单 | E62: 全栈 | F62: 销售订单列表（与 FP5-01 同页两线） | G62: V1.0 | H62: 1.5 | I62: =H62*(1+汇总!$C$46) -> 1.725 | J62: 徐蔚 | K62: 46293 | L62: 46294
A63: B8 | B63: 采购管理 | C63: （待补） | D63: 采购退货单：收货拒收/入库后退货·可退上限·关联采购入库 | E63: 全栈 | F63: 采购退货单列表+新建弹窗 | G63: V1.0 | H63: 1.5 | I63: =H63*(1+汇总!$C$46) -> 1.725 | J63: 徐蔚 | K63: 46294 | L63: 46295 | M63: G33·D-123（方案 B）→应付退款（对供应商）；人日待开发重估
A64: C1 | B64: 测试 | C64: — | D64: 集成测试用例编写与执行（F01 v3.6 七泳道 B1/L1-L4/T1/T2 + 16 类待办） | E64: 测试 | F64: F01 导航图 v3.6 | G64: 各版 | H64: 10 | I64: =H64*(1+汇总!$C$46) -> 11.5 | J64: 徐蔚 | K64: 46308 | L64: 46367 | M64: 覆盖五条主线+财务双通道；B1 采购线（09-04 拍板，不以销定采）
A65: C1 | B65: 测试 | C65: — | D65: UAT 支持与缺陷修复 | E65: 测试 | F65: — | G65: 各版 | H65: 7 | I65: =H65*(1+汇总!$C$46) -> 8.05 | J65: 徐蔚 | K65: 46314 | L65: 46370
...
