Workbook

Sheet 版本交付阶梯图

Sheet 汇总
A1: 汇总与折算（公式驱动，唯一维护处）
A3: WBS | B3: 模块/阶段 | C3: 人日小计 | D3: 开始日期 | E3: 结束日期 | F3: 关键风险/依赖
A4: A1 | B4: 需求调研与PRD | C4: =SUMIF('功能点评估（全栈）'!$A$4:$A$69,$A4,'功能点评估（全栈）'!$H$4:$H$69) -> 6 | D4: =IF(COUNT('功能点评估（全栈）'!K4:K7)=0,"",MIN('功能点评估（全栈）'!K4:K7)) -> 46272 | E4: =IF(COUNT('功能点评估（全栈）'!L4:L7)=0,"",MAX('功能点评估（全栈）'!L4:L7)) -> 46276 | F4: #2 #3 材料未齐即启动，PRD 有返工风险
A5: A2 | B5: 原型设计 | C5: =SUMIF('功能点评估（全栈）'!$A$4:$A$69,$A5,'功能点评估（全栈）'!$H$4:$H$69) -> 1 | D5: =IF(COUNT('功能点评估（全栈）'!K8:K9)=0,"",MIN('功能点评估（全栈）'!K8:K9)) -> 46275 | E5: =IF(COUNT('功能点评估（全栈）'!L8:L9)=0,"",MAX('功能点评估（全栈）'!L8:L9)) -> 46276 | F5: v2.8 已交付，仅评修订量
A6: B0 | B6: 公共技术底座 | C6: =SUMIF('功能点评估（全栈）'!$A$4:$A$69,$A6,'功能点评估（全栈）'!$H$4:$H$69) -> 5.5 | D6: =IF(COUNT('功能点评估（全栈）'!K10:K12)=0,"",MIN('功能点评估（全栈）'!K10:K12)) -> 46272 | E6: =IF(COUNT('功能点评估（全栈）'!L10:L12)=0,"",MAX('功能点评估（全栈）'!L10:L12)) -> 46275
A7: B1 | B7: 基础数据 | C7: =SUMIF('功能点评估（全栈）'!$A$4:$A$69,$A7,'功能点评估（全栈）'!$H$4:$H$69) -> 9.5 | D7: =IF(COUNT('功能点评估（全栈）'!K13:K18)=0,"",MIN('功能点评估（全栈）'!K13:K18)) -> 46275 | E7: =IF(COUNT('功能点评估（全栈）'!L13:L18)=0,"",MAX('功能点评估（全栈）'!L13:L18)) -> 46316
A8: B2 | B8: 项目管理中心 | C8: =SUMIF('功能点评估（全栈）'!$A$4:$A$69,$A8,'功能点评估（全栈）'!$H$4:$H$69) -> 6.5 | D8: =IF(COUNT('功能点评估（全栈）'!K19:K23)=0,"",MIN('功能点评估（全栈）'!K19:K23)) -> 46275 | E8: =IF(COUNT('功能点评估（全栈）'!L19:L23)=0,"",MAX('功能点评估（全栈）'!L19:L23)) -> 46308
A9: B3 | B9: 仓储作业 ★核心 | C9: =SUMIF('功能点评估（全栈）'!$A$4:$A$69,$A9,'功能点评估（全栈）'!$H$4:$H$69) -> 27.5 | D9: =IF(COUNT('功能点评估（全栈）'!K24:K36)=0,"",MIN('功能点评估（全栈）'!K24:K36)) -> 46276 | E9: =IF(COUNT('功能点评估（全栈）'!L24:L36)=0,"",MAX('功能点评估（全栈）'!L24:L36)) -> 46342 | F9: 13 类单据；组装/拆卸为全新逻辑，PRD 冻结前估算偏差大
A10: B4 | B10: 包装管理（租赁） | C10: =SUMIF('功能点评估（全栈）'!$A$4:$A$69,$A10,'功能点评估（全栈）'!$H$4:$H$69) -> 13.5 | D10: =IF(COUNT('功能点评估（全栈）'!K37:K42)=0,"",MIN('功能点评估（全栈）'!K37:K42)) -> 46307 | E10: =IF(COUNT('功能点评估（全栈）'!L37:L42)=0,"",MAX('功能点评估（全栈）'!L37:L42)) -> 46331 | F10: #1 计费规则未确认（US-14 暂不在基线）
A11: B5 | B11: 订单管理 | C11: =SUMIF('功能点评估（全栈）'!$A$4:$A$69,$A11,'功能点评估（全栈）'!$H$4:$H$69) -> 9 | D11: =IF(COUNT('功能点评估（全栈）'!K43:K46)=0,"",MIN('功能点评估（全栈）'!K43:K46)) -> 46276 | E11: =IF(COUNT('功能点评估（全栈）'!L43:L46)=0,"",MAX('功能点评估（全栈）'!L43:L46)) -> 46343 | F11: #6 路凯对接方式待定
A12: B6 | B12: 财务协同 | C12: =SUMIF('功能点评估（全栈）'!$A$4:$A$69,$A12,'功能点评估（全栈）'!$H$4:$H$69) -> 15.5 | D12: =IF(COUNT('功能点评估（全栈）'!K47:K53)=0,"",MIN('功能点评估（全栈）'!K47:K53)) -> 46282 | E12: =IF(COUNT('功能点评估（全栈）'!L47:L53)=0,"",MAX('功能点评估（全栈）'!L47:L53)) -> 46349 | F12: #5 单据/水单样例、#8 开票主体待提供
A13: B7 | B13: 系统管理 | C13: =SUMIF('功能点评估（全栈）'!$A$4:$A$69,$A13,'功能点评估（全栈）'!$H$4:$H$69) -> 2 | D13: =IF(COUNT('功能点评估（全栈）'!K54:K56)=0,"",MIN('功能点评估（全栈）'!K54:K56)) -> 46289 | E13: =IF(COUNT('功能点评估（全栈）'!L54:L56)=0,"",MAX('功能点评估（全栈）'!L54:L56)) -> 46342
A14: B8 | B14: 采购管理 | C14: =SUMIF('功能点评估（全栈）'!$A$4:$A$69,$A14,'功能点评估（全栈）'!$H$4:$H$69) -> 8 | D14: =IF(COUNT('功能点评估（全栈）'!K57:K61)=0,"",MIN('功能点评估（全栈）'!K57:K61)) -> 46286 | E14: =IF(COUNT('功能点评估（全栈）'!L57:L61)=0,"",MAX('功能点评估（全栈）'!L57:L61)) -> 46336 | F14: 第 2 次会新增模块（09-04 拍板第一期闭环）
A15: C1 | B15: 测试 | C15: =SUMIF('功能点评估（全栈）'!$A$4:$A$69,$A15,'功能点评估（全栈）'!$H$4:$H$69) -> 17 | D15: =IF(COUNT('功能点评估（全栈）'!K62:K63)=0,"",MIN('功能点评估（全栈）'!K62:K63)) -> 46303 | E15: =IF(COUNT('功能点评估（全栈）'!L62:L63)=0,"",MAX('功能点评估（全栈）'!L62:L63)) -> 46360 | F15: 用例需覆盖 F01 五条主线全链路
A16: C2 | B16: 数据迁移 | C16: =SUMIF('功能点评估（全栈）'!$A$4:$A$69,$A16,'功能点评估（全栈）'!$H$4:$H$69) -> 13 | D16: =IF(COUNT('功能点评估（全栈）'!K64:K66)=0,"",MIN('功能点评估（全栈）'!K64:K66)) -> 46303 | E16: =IF(COUNT('功能点评估（全栈）'!L64:L66)=0,"",MAX('功能点评估（全栈）'!L64:L66)) -> 46360 | F16: #4 主数据清单与格式待提供
A17: C3 | B17: 上线部署 | C17: =SUMIF('功能点评估（全栈）'!$A$4:$A$69,$A17,'功能点评估（全栈）'!$H$4:$H$69) -> 15 | D17: =IF(COUNT('功能点评估（全栈）'!K67:K69)=0,"",MIN('功能点评估（全栈）'!K67:K69)) -> 46308 | E17: =IF(COUNT('功能点评估（全栈）'!L67:L69)=0,"",MAX('功能点评估（全栈）'!L67:L69)) -> 46374 | F17: 试运行窗口待与客户确认
B18: 合计 / 全跨度 | C18: =SUM(C4:C17) -> 149 | D18: =IF(COUNT(D4:D17)=0,"",MIN(D4:D17)) -> 46272 | E18: =IF(COUNT(E4:E17)=0,"",MAX(E4:E17)) -> 46374
A20: 版本里程碑（人日 × 上线节点 × 范围，合并原「版本小计 + 里程碑一览」）
A21: 版本 | B21: 上线 / 完成节点 | C21: 范围与业务 | D21: 人日小计 | E21: 含缓冲 | F21: 开始日期 | G21: 结束日期 | H21: 无AI对照 （方案1·212人日）
A22: 前置 | B22: 09-07 ~ 09-11 定版 | C22: 走查 45 页 + 计费确认 + PRD 冻结 + 芋道底座/编码规范 | D22: =SUMIF('功能点评估（全栈）'!$G$4:$G$69,$A22,'功能点评估（全栈）'!$H$4:$H$69) -> 12.5 | E22: =ROUND(D22*(1+$C$46),2) -> 14.38 | F22: 46272 | G22: 46276 | H22: 无AI 09-16
A23: V1.0 | B23: ★ 10-16 上线 | C23: 买卖版 17 页：买卖全链 + 库存（查询/调拨/其他出入库）+ 应收/回款 + 权限；零新逻辑 | D23: =SUMIF('功能点评估（全栈）'!$G$4:$G$69,$A23,'功能点评估（全栈）'!$H$4:$H$69) -> 32.5 | E23: =ROUND(D23*(1+$C$46),2) -> 37.38 | F23: 46275 | G23: 46294 | H23: 无AI 10-30
A24: V1.1 | B24: ★ 11-17 上线 | C24: 租赁版 +20 页：租赁循环（组装/租赁单/退租/四态）+ BOM + 丢损赔偿 + 应付简化 + 待办 + 移入的盘点/看板/详情 | D24: =SUMIF('功能点评估（全栈）'!$G$4:$G$69,$A24,'功能点评估（全栈）'!$H$4:$H$69) -> 39 | E24: =ROUND(D24*(1+$C$46),2) -> 44.85 | F24: 46282 | G24: 46331 | H24: 无AI 12-10
A25: V2.0 | B25: ★ 12-07 上线 | C25: 深化版 +8 页：租入三单（L3/L4）+ 路凯对接 + 财务收口（开票/水单核销/盈亏）+ 日志字典；旧系统全停用 | D25: =SUMIF('功能点评估（全栈）'!$G$4:$G$69,$A25,'功能点评估（全栈）'!$H$4:$H$69) -> 20 | E25: =ROUND(D25*(1+$C$46),2) -> 23 | F25: 46332 | G25: 46349 | H25: 无AI 01-15
A26: 验收收口 | B26: 12-25 前后 | C26: 试运行 2 周（真实订单并行）+ 年内验收；富余产能启动 2027 backlog | H26: 无AI 2027-01-31
A27: 各版 | B27: 10-08 / 11-09 / 12-01 启动 | C27: 测试 / UAT / 数据迁移 / 部署 / 切换 / 试运行——每版上线前各跑一轮（单轮 15 人日×3） | D27: =SUMIF('功能点评估（全栈）'!$G$4:$G$69,$A27,'功能点评估（全栈）'!$H$4:$H$69) -> 45 | E27: =ROUND(D27*(1+$C$46),2) -> 51.75 | F27: 46303 | G27: 46374 | H27: —
C28: 版本人日合计（校验=总合计 C18） | D28: =SUM(D22:D27) -> 149 | E28: =IF(D28=C18,"✓ 一致","✗ 不一致") -> ✓ 一致
A30: 按月负载（原「按月版本规划」主体并入）
A31: 月份 | B31: 计划人日 （含缓冲） | C31: 当月产能 （人日） | D31: 负载率 | E31: 当月里程碑与内容摘要
A32: 2026-09 | B32: 59.2 | C32: 54 | D32: =B32/C32 -> 1.0962963 | E32: 09-09 底座+规范就绪；09-11 PRD 冻结；09-10 起 V1.0 全量开发（基础数据/项目域/买卖链），09-30 功能开发完成｜注：本列计划人日=按行级排期逐日分摊（09-07 重排后口径）；9 月 110% 负载系 A1-03 由 Claude 并行起草、徐蔚 V1.0 后闲窗提前开工 V1.1 所致，人工产能按 3 人计、总量已含 15% 缓冲
A33: 2026-10 | B33: 48.5 | C33: 48 | D33: =B33/C33 -> 1.0104167 | E33: 10-08~15 轮1：集成测试/UAT/主数据迁移/部署；★10-16 V1.0 买卖版上线（17 页）；10-19 起 V1.1 主开发（国庆仅 16 工作日，满负荷）
A34: 2026-11 | B34: 57 | C34: 63 | D34: =B34/C34 -> 0.9047619 | E34: 11-06 V1.1 开发完成；11-09~16 轮2（BOM/在租迁移）；★11-17 V1.1 租赁版上线（累计 37 页）；11-17~26 V2.0 开发
A35: 2026-12 | B35: 6.7 | C35: 69 | D35: =B35/C35 -> 0.097101449 | E35: 12-01~04 轮3（租入在途迁移/部署）；★12-07 V2.0 全量上线（45 页）；12-07~18 试运行；12-25 前后项目验收收口
A36: 合计 | B36: =SUM(B32:B35) -> 171.4 | C36: =SUM(C32:C35) -> 234 | D36: =B36/C36 -> 0.73247863
A38: AI 协作（Claude Code）前提与风险
A39: R1 评审带宽 | B39: AI 产出量大，3 名工程师须固定每日代码评审时段消化
A40: R2 风格统一 | B40: 底座周（09-09~10）必须落编码规范与组件约定，统一三套 AI 风格
A41: R3 关键逻辑 | B41: 库存过账/组装拆卸/四态计费/水单核销以人工设计主导，勿盲信 AI 产出
A42: R4 磨合回退 | B42: 若 AI 协作磨合不顺（提速退化），工期按 212 人日口径上浮，里程碑顺延
A43: R5 外部依赖 | B43: #6 路凯对接方式、#5 水单样例、#8 开票主体——未定项集中在 V2.0 前必须落实
A45: 参数与折算
...

Sheet 甘特图-功能点级
A1: 甘特图 · WBS × 版本（30 行概览版）
A2: 口径：横轴为工作日（09-07 ~ 12-25，共 75 天，已跳双休与国庆 10-01~07）；每条 = 该版本下该模块全部任务的实际起止（快照自「功能点评估（全栈）」，重排后需刷新）；红竖列 = 版本上线里程碑（10-16 / 11-17 / 12-07 / 12-25 验收）；蓝竖列 = 今日。
A3: WBS | B3: 模块 / 内容 | C3: 人日 | D3: 开始 | E3: 结束 | F3: 2026-09 | X3: 2026-10（国庆后） | AO3: 2026-11 | BJ3: 2026-12
F4: 46272 | G4: 46273 | H4: 46274 | I4: 46275 | J4: 46276 | K4: 46279 | L4: 46280 | M4: 46281 | N4: 46282 | O4: 46283 | P4: 46286 | Q4: 46287 | R4: 46288 | S4: 46289 | T4: 46290 | U4: 46293 | V4: 46294 | W4: 46295 | X4: 46303 | Y4: 46304 | Z4: 46307 | AA4: 46308 | AB4: 46309 | AC4: 46310 | AD4: 46311 | AE4: 46314 | AF4: 46315 | AG4: 46316 | AH4: 46317 | AI4: 46318 | AJ4: 46321 | AK4: 46322 | AL4: 46323 | AM4: 46324 | AN4: 46325 | AO4: 46328 | AP4: 46329 | AQ4: 46330 | AR4: 46331 | AS4: 46332 | AT4: 46335 | AU4: 46336 | AV4: 46337 | AW4: 46338 | AX4: 46339 | AY4: 46342 | AZ4: 46343 | BA4: 46344 | BB4: 46345 | BC4: 46346 | BD4: 46349 | BE4: 46350 | BF4: 46351 | BG4: 46352 | BH4: 46353 | BI4: 46356 | BJ4: 46357 | BK4: 46358 | BL4: 46359 | BM4: 46360 | BN4: 46363 | BO4: 46364 | BP4: 46365 | BQ4: 46366 | BR4: 46367 | BS4: 46370 | BT4: 46371 | BU4: 46372 | BV4: 46373 | BW4: 46374 | BX4: 46377 | BY4: 46378 | BZ4: 46379 | CA4: 46380 | CB4: 46381
A5: 前置（09-07 ~ 09-11）
A6: A1 | B6: 需求调研与 PRD（走查/计费/评审冻结） | C6: 6 | D6: 46272 | E6: 46276
A7: A2 | B7: 原型修订与定稿 | C7: 1 | D7: 46275 | E7: 46276
A8: B0 | B8: 技术底座（脚手架/登录/通用组件） | C8: 5.5 | D8: 46272 | E8: 46275
A9: V1.0 买卖版 ★ 10-16 上线
A10: B1 | B10: 基础数据：档案五件套（除 BOM） | C10: 6.5 | D10: 46275 | E10: 46283
A11: B2 | B11: 项目域：编码规则 + 上下游绑定 | C11: 1.5 | D11: 46275 | E11: 46276
A12: B3 | B12: 仓储：采购入库/库存查询/出入库/调拨 | C12: 10.5 | D12: 46276 | E12: 46293
A13: B5 | B13: 订单：代下单 + 审核 | C13: 3 | D13: 46276 | E13: 46281
A14: B6 | B14: 财务：应收账单 + 回款 | C14: 4 | D14: 46282 | E14: 46288
A15: B7 | B15: 用户权限 | C15: 1 | D15: 46289 | E15: 46289
A16: B8 | B16: 采购管理：订单/审核/入库发起/销售订单 | C16: 6 | D16: 46286 | E16: 46294
A17: V1.1 租赁版 ★ 11-17 上线
A18: B1 | B18: BOM 维护（版本 + 配比校验） | C18: 3 | D18: 46314 | E18: 46316
A19: B2 | B19: 看板 / 详情 / 我的待办 | C19: 5 | D19: 46290 | E19: 46308
A20: B3 | B20: 组装★ / 组合出库 / 退租 / 拆卸 | C20: 14 | D20: 46309 | E20: 46329
A21: B4 | B21: 包装管理：租赁单/四态/赔偿/退租申请 | C21: 13.5 | D21: 46307 | E21: 46331
A22: B6 | B22: 应付账单（简化）+ 付款登记 | C22: 3.5 | D22: 46282 | E22: 46289
A23: V2.0 深化版 ★ 12-07 上线
A24: B3 | B24: 租入入库 / 租入归还 | C24: 3 | D24: 46337 | E24: 46342
A25: B5 | B25: 路凯订单同步 + 结算导出 | C25: 6 | D25: 46335 | E25: 46343
A26: B6 | B26: 开票 / 水单核销★ / 项目盈亏 | C26: 8 | D26: 46337 | E26: 46349
A27: B7 | B27: 操作日志 + 数据字典 | C27: 1 | D27: 46339 | E27: 46342
A28: B8 | B28: 租入单 | C28: 2 | D28: 46332 | E28: 46336
A29: 各版支撑（测试 / 迁移 / 上线 · 每版一轮）
A30: C1 | B30: 集成测试 / UAT（轮1·2·3） | C30: 17 | D30: 46303 | E30: 46360
A31: C2 | B31: 数据迁移（主数据/期初/核对） | C31: 13 | D31: 46303 | E31: 46360
A32: C3 | B32: 部署 / 上线切换 / 试运行 | C32: 15 | D32: 46308 | E32: 46374

Sheet 甘特图-任务级
A1: 甘特图 · 任务级（66 行全量）
A2: 口径：横轴 75 个工作日（09-07~12-25，跳双休与国庆）；每行 = 一个功能点任务，条色按版本；红竖列 = 上线里程碑；黄竖列 = 今日。与「功能点评估（全栈）」1:1，改排期后需刷新。
A3: WBS | B3: 功能点 | C3: 任务 | D3: 版本 | E3: 人日 | F3: 开始 | G3: 结束 | H3: 9月 | Z3: 10月 | AQ3: 11月 | BL3: 12月
H4: 46272 | I4: 46273 | J4: 46274 | K4: 46275 | L4: 46276 | M4: 46279 | N4: 46280 | O4: 46281 | P4: 46282 | Q4: 46283 | R4: 46286 | S4: 46287 | T4: 46288 | U4: 46289 | V4: 46290 | W4: 46293 | X4: 46294 | Y4: 46295 | Z4: 46303 | AA4: 46304 | AB4: 46307 | AC4: 46308 | AD4: 46309 | AE4: 46310 | AF4: 46311 | AG4: 46314 | AH4: 46315 | AI4: 46316 | AJ4: 46317 | AK4: 46318 | AL4: 46321 | AM4: 46322 | AN4: 46323 | AO4: 46324 | AP4: 46325 | AQ4: 46328 | AR4: 46329 | AS4: 46330 | AT4: 46331 | AU4: 46332 | AV4: 46335 | AW4: 46336 | AX4: 46337 | AY4: 46338 | AZ4: 46339 | BA4: 46342 | BB4: 46343 | BC4: 46344 | BD4: 46345 | BE4: 46346 | BF4: 46349 | BG4: 46350 | BH4: 46351 | BI4: 46352 | BJ4: 46353 | BK4: 46356 | BL4: 46357 | BM4: 46358 | BN4: 46359 | BO4: 46360 | BP4: 46363 | BQ4: 46364 | BR4: 46365 | BS4: 46366 | BT4: 46367 | BU4: 46370 | BV4: 46371 | BW4: 46372 | BX4: 46373 | BY4: 46374 | BZ4: 46377 | CA4: 46378 | CB4: 46379 | CC4: 46380 | CD4: 46381
A5: 前置（09-07 ~ 09-11）
A6: A1 | B6: — | C6: 原型页面走查与字段确认（45 页逐页过… | D6: 前置 | E6: 1.5 | F6: 46272 | G6: 46273
A7: A1 | B7: — | C7: 计费规则与单据流程确认（含四态计费口径） | D7: 前置 | E7: 2 | F7: 46274 | G7: 46275
A8: A1 | B8: — | C8: PRD 编写（按模块分册，以原型页面为… | D8: 前置 | E8: 1.5 | F8: 46274 | G8: 46275
A9: A1 | B9: — | C9: PRD 评审与范围冻结 | D9: 前置 | E9: 1 | F9: 46276 | G9: 46276
A10: A2 | B10: — | C10: 原型按评审反馈修订 | D10: 前置 | E10: 0.5 | F10: 46275 | G10: 46275
A11: A2 | B11: — | C11: 原型评审确认与定稿 | D11: 前置 | E11: 0.5 | F11: 46276 | G11: 46276
A12: B0 | B12: — | C12: 工程脚手架与 CI/CD | D12: 前置 | E12: 1.5 | F12: 46272 | G12: 46273
A13: B0 | B13: — | C13: 登录认证与框架权限 | D13: 前置 | E13: 0.5 | F13: 46274 | G13: 46274
A14: B0 | B14: — | C14: 通用组件（单据/列表/导入导出/弹窗/… | D14: 前置 | E14: 3.5 | F14: 46274 | G14: 46275
A15: V1.0 买卖版 ★ 10-16 上线
A16: B1 | B16: FP1-01 | C16: 项目档案：页面 + 表结构与接口 | D16: V1.0 | E16: 1.5 | F16: 46275 | G16: 46276
A17: B1 | B17: FP1-02 | C17: 客商管理：三类客商档案（含开票资料） | D17: V1.0 | E17: 2 | F17: 46279 | G17: 46280
A18: B1 | B18: FP1-03 | C18: 器具档案：页面 + 接口 | D18: V1.0 | E18: 1 | F18: 46281 | G18: 46281
A19: B1 | B19: FP1-04 | C19: 零部件档案：页面 + 接口 | D19: V1.0 | E19: 1 | F19: 46282 | G19: 46282
A20: B1 | B20: FP1-06 | C20: 库位档案：页面 + 接口（仓/区/位三… | D20: V1.0 | E20: 1 | F20: 46283 | G20: 46283
A21: B2 | B21: FP2-01 | C21: 项目编码规则：规则引擎 + 配置 | D21: V1.0 | E21: 0.5 | F21: 46275 | G21: 46275
A22: B2 | B22: FP2-02 | C22: 上下游绑定：关系维护 + 模型接口 | D22: V1.0 | E22: 1 | F22: 46276 | G22: 46276
A23: B3 | B23: FP3-01 | C23: 采购入库单（执行）：录单 + 入库过账… | D23: V1.0 | E23: 2 | F23: 46276 | G23: 46279
A24: B3 | B24: FP3-06 | C24: 库存查询：零件/组合双视角 + 库存流水 | D24: V1.0 | E24: 2 | F24: 46280 | G24: 46281
A25: B3 | B25: （待补） | C25: 销售出库单：录单 + 出库过账（买卖线… | D25: V1.0 | E25: 2 | F25: 46282 | G25: 46283
A26: B3 | B26: （待补） | C26: 其他入库单：无单据来源杂项入库 | D26: V1.0 | E26: 1.5 | F26: 46286 | G26: 46287
A27: B3 | B27: （待补） | C27: 其他出库单：报废/杂项出库 | D27: V1.0 | E27: 1.5 | F27: 46288 | G27: 46289
... A37: B8 | B37: FP8-04 | C37: 销售订单（买卖线）：客户购买订单 | D37: V1.0 | E37: 1.5 | F37: 46293 | G37: 46294
A38: V1.1 租赁版 ★ 11-17 上线
A39: B1 | B39: FP1-05 | C39: 子母件 BOM：维护页 + 版本管理与… | D39: V1.1 | E39: 3 | F39: 46314 | G39: 46316
A40: B2 | B40: FP2-03 | C40: 项目看板：图表页 + 统计接口 | D40: V1.1 | E40: 1.5 | F40: 46290 | G40: 46293
A41: B2 | B41: FP2-04 | C41: 明细查看：从汇总数据进入单据明细 | D41: V1.1 | E41: 1.5 | F41: 46294 | G41: 46295
A42: B2 | B42: （待补） | C42: 我的待办：18 类待办聚合入口 | D42: V1.1 | E42: 2 | F42: 46304 | G42: 46308
A43: B3 | B43: FP3-02 ★新增 | C43: 组装单：录单 + 库存转换引擎（A+B… | D43: V1.1 | E43: 4 | F43: 46314 | G43: 46318
A44: B3 | B44: FP3-03 | C44: 组合出库单：录单 + 出库过账与台账联动 | D44: V1.1 | E44: 2 | F44: 46321 | G44: 46322
A45: B3 | B45: FP3-04 | C45: 退租入库验收单：按零件核对缺损并记明细 | D45: V1.1 | E45: 2 | F45: 46323 | G45: 46324
A46: B3 | B46: FP3-05 | C46: 盘点单：零件/组合双口径 + 盘盈亏过账 | D46: V1.1 | E46: 3 | F46: 46309 | G46: 46311
A47: B3 | B47: （待补） | C47: 拆卸单：C→A+B 逆向、散件回库 | D47: V1.1 | E47: 3 | F47: 46325 | G47: 46329
A48: B4 | B48: FP4-01 | C48: 租出台账：页面 + 接口 | D48: V1.1 | E48: 1.5 | F48: 46317 | G48: 46318
A49: B4 | B49: FP4-02 | C49: 在租台账：在库/在途/客户端/退租四态… | D49: V1.1 | E49: 3 | F49: 46321 | G49: 46323
...

Sheet 功能点评估（全栈）
A1: P1-R03 工期评估表 · 功能点级（全栈口径）
A2: 口径：人日含概要设计+编码+自测；每功能点一行、不分前后端（类型=全栈）。2026-09-05 按方案二（买卖先行）标定「版本」列：V1.0 买卖版 21 页 / V1.1 租赁版 +16 页 / V2.0 深化版 +8 页，前置=调研+底座、各版=测试迁移上线每版重复投入。标（待补）的 10 行为原型已有但 §5.1 未编 FP 码的页面。人日/评估人/开始/结束全部留白，由道远与开发逐行填写；上一版估算归档于 99-归档/P1-R03-工期评估表-20260905.xlsx。｜2026-09-06 更新：按 3 名全栈开发、2026-09-07~09-10 芋道（yudao）JDK21 底座搭建、09-10 起业务开发、原型基本确定（前置压缩）口径填入人日初评；「各版」行 H=单轮人日×3 版；评估人/起止列留白待道远与开发复核微调。｜2026-09-06 二次调整：为赶 V1.0 于 2026-10-30 上线，盘点单（FP3-05）/项目看板（FP2-03）/项目详情（FP2-04）共 8.5 人日移至 V1.1——V1.0 缩为 17 页、V1.1 扩为 +20 页，总人日不变。｜2026-09-06 方案 2.0：3 名全栈全部借助 Claude Code vibe coding，按净提速口径重估——列表/弹窗/文档类×0.6、录单+过账×0.7、复杂业务逻辑（库存过账/组装拆卸/计费/核销/路凯对接）×0.75~0.85（人工设计主导）、调研评审不提速；整体 212→149 人日（-29.6%），15% 缓冲与版本范围不变。｜I 列「含缓冲人日」=H×(1+汇总!C30) 自动计算，与「按月版本规划」口径统一（171.35），汇报用 I 列。
A3: WBS | B3: 模块/阶段 | C3: 功能点 | D3: 任务 | E3: 类型 | F3: 对应原型页面 | G3: 版本 | H3: 人日 | I3: 含缓冲人日 （=人日×1.15） | J3: 评估人 | K3: 开始时间 | L3: 结束时间 | M3: 备注（风险/依赖）
A4: A1 | B4: 需求调研与PRD | C4: — | D4: 原型页面走查与字段确认（45 页逐页过、与吉客云/路凯现状对照） | E4: 调研 | F4: 45 页全量 | G4: 前置 | H4: 1.5 | I4: =H4*(1+汇总!$C$46) -> 1.725 | J4: 吕道远 | K4: 46272 | L4: 46273 | M4: 依赖 #2 #3：账号或全套截图；走查结论直接落到 PRD
A5: A1 | B5: 需求调研与PRD | C5: — | D5: 计费规则与单据流程确认（含四态计费口径） | E5: 调研 | F5: — | G5: 前置 | H5: 2 | I5: =H5*(1+汇总!$C$46) -> 2.3 | J5: 吕道远 | K5: 46274 | L5: 46275 | M5: 依赖 #1 #5：合同/报价单、单据样例
A6: A1 | B6: 需求调研与PRD | C6: — | D6: PRD 编写（按模块分册，以原型页面为底稿） | E6: 文档 | F6: 45 页全量 | G6: 前置 | H6: 1.5 | I6: =H6*(1+汇总!$C$46) -> 1.725 | J6: 吕道远 | K6: 46274 | L6: 46275
A7: A1 | B7: 需求调研与PRD | C7: — | D7: PRD 评审与范围冻结 | E7: 文档 | F7: 45 页全量 | G7: 前置 | H7: 1 | I7: =H7*(1+汇总!$C$46) -> 1.15 | J7: 吕道远 | K7: 46276 | L7: 46276 | M7: 客户确认后冻结范围，原型同步定稿
A8: A2 | B8: 原型设计 | C8: — | D8: 原型按评审反馈修订 | E8: 原型 | F8: 涉及页视反馈 | G8: 前置 | H8: 0.5 | I8: =H8*(1+汇总!$C$46) -> 0.575 | J8: 吕道远 | K8: 46275 | L8: 46275 | M8: v2.8 已交付（45 页 + 79 弹窗 + F01 导航图），仅评修订量，勿按全量重估
A9: A2 | B9: 原型设计 | C9: — | D9: 原型评审确认与定稿 | E9: 原型 | F9: 45 页全量 + F01 | G9: 前置 | H9: 0.5 | I9: =H9*(1+汇总!$C$46) -> 0.575 | J9: 吕道远 | K9: 46276 | L9: 46276 | M9: 与 PRD 冻结同节点收口
A10: B0 | B10: 公共技术底座 | C10: — | D10: 工程脚手架与 CI/CD | E10: 全栈 | F10: — | G10: 前置 | H10: 1.5 | I10: =H10*(1+汇总!$C$46) -> 1.725 | J10: 徐蔚 | K10: 46272 | L10: 46273 | M10: 本表新增项，非 P1-R01 功能点，评估时确认保留
A11: B0 | B11: 公共技术底座 | C11: — | D11: 登录认证与框架权限 | E11: 全栈 | F11: — | G11: 前置 | H11: 0.5 | I11: =H11*(1+汇总!$C$46) -> 0.575 | J11: 徐蔚 | K11: 46274 | L11: 46274 | M11: 原型未含登录页，按通用方案实现
A12: B0 | B12: 公共技术底座 | C12: — | D12: 通用组件（单据/列表/导入导出/弹窗/四段式详情） | E12: 全栈 | F12: 全站 | G12: 前置 | H12: 3.5 | I12: =H12*(1+汇总!$C$46) -> 4.025 | J12: 徐蔚 | K12: 46274 | L12: 46275 | M12: 复刻原型交互；79 个弹窗模板与四段式详情组件可直接参照
A13: B1 | B13: 基础数据 | C13: FP1-01 | D13: 项目档案：页面 + 表结构与接口 | E13: 全栈 | F13: 项目档案 | G13: V1.0 | H13: 1.5 | I13: =H13*(1+汇总!$C$46) -> 1.725 | J13: 徐蔚 | K13: 46275 | L13: 46276
A14: B1 | B14: 基础数据 | C14: FP1-02 | D14: 客商管理：三类客商档案（含开票资料） | E14: 全栈 | F14: 客商管理 | G14: V1.0 | H14: 2 | I14: =H14*(1+汇总!$C$46) -> 2.3 | J14: 徐蔚 | K14: 46279 | L14: 46280
A15: B1 | B15: 基础数据 | C15: FP1-03 | D15: 器具档案：页面 + 接口 | E15: 全栈 | F15: 器具档案 | G15: V1.0 | H15: 1 | I15: =H15*(1+汇总!$C$46) -> 1.15 | J15: 徐蔚 | K15: 46281 | L15: 46281
A16: B1 | B16: 基础数据 | C16: FP1-04 | D16: 零部件档案：页面 + 接口 | E16: 全栈 | F16: 零部件档案 | G16: V1.0 | H16: 1 | I16: =H16*(1+汇总!$C$46) -> 1.15 | J16: 徐蔚 | K16: 46282 | L16: 46282
A17: B1 | B17: 基础数据 | C17: FP1-05 | D17: 子母件 BOM：维护页 + 版本管理与配比校验 | E17: 全栈 | F17: BOM + BOM维护（2页） | G17: V1.1 | H17: 3 | I17: =H17*(1+汇总!$C$46) -> 3.45 | J17: 徐蔚 | K17: 46314 | L17: 46316 | M17: 配比错误需拦截；BOM 仅租赁域使用，随租赁版上线
A18: B1 | B18: 基础数据 | C18: FP1-06 | D18: 库位档案：页面 + 接口（仓/区/位三级） | E18: 全栈 | F18: 库位档案 | G18: V1.0 | H18: 1 | I18: =H18*(1+汇总!$C$46) -> 1.15 | J18: 徐蔚 | K18: 46283 | L18: 46283 | M18: 预留扫码接口（REQ-20）
A19: B2 | B19: 项目管理中心 | C19: FP2-01 | D19: 项目编码规则：规则引擎 + 配置 | E19: 全栈 | F19: 项目档案（编码规则弹窗） | G19: V1.0 | H19: 0.5 | I19: =H19*(1+汇总!$C$46) -> 0.575 | J19: 徐蔚 | K19: 46275 | L19: 46275
A20: B2 | B20: 项目管理中心 | C20: FP2-02 | D20: 上下游绑定：关系维护 + 模型接口 | E20: 全栈 | F20: 项目档案（上下游绑定弹窗） | G20: V1.0 | H20: 1 | I20: =H20*(1+汇总!$C$46) -> 1.15 | J20: 徐蔚 | K20: 46276 | L20: 46276
A21: B2 | B21: 项目管理中心 | C21: FP2-03 | D21: 项目看板：图表页 + 统计接口 | E21: 全栈 | F21: 首页·项目看板 | G21: V1.1 | H21: 1.5 | I21: =H21*(1+汇总!$C$46) -> 1.725 | J21: 徐蔚 | K21: 46290 | L21: 46293 | M21: V1.0→V1.1（2026-09-06 赶 10 月上线范围调整）
A22: B2 | B22: 项目管理中心 | C22: FP2-04 | D22: 明细查看：从汇总数据进入单据明细 | E22: 全栈 | F22: 项目详情 | G22: V1.1 | H22: 1.5 | I22: =H22*(1+汇总!$C$46) -> 1.725 | J22: 徐蔚 | K22: 46294 | L22: 46295 | M22: V1.0→V1.1（2026-09-06 赶 10 月上线范围调整）
A23: B2 | B23: 项目管理中心 | C23: （待补） | D23: 我的待办：18 类待办聚合入口 | E23: 全栈 | F23: 首页·我的待办 | G23: V1.1 | H23: 2 | I23: =H23*(1+汇总!$C$46) -> 2.3 | J23: 徐蔚 | K23: 46304 | L23: 46308 | M23: FP 码待补（§5.1 未编）；聚合各模块待办，单据类型齐了才有意义，随租赁版
A24: B3 | B24: 仓储作业 ★核心 | C24: FP3-01 | D24: 采购入库单（执行）：录单 + 入库过账与库存更新 | E24: 全栈 | F24: 采购入库 列表+录单（2页） | G24: V1.0 | H24: 2 | I24: =H24*(1+汇总!$C$46) -> 2.3 | J24: 徐蔚 | K24: 46276 | L24: 46279 | M24: V1.0 无采购订单时先手工入库（同吉客云现状），V1.0 内衔接 FP8-03 凭单发起
A25: B3 | B25: 仓储作业 ★核心 | C25: FP3-02 ★新增 | D25: 组装单：录单 + 库存转换引擎（A+B→C） | E25: 全栈 | F25: 组装 列表+录单（2页） | G25: V1.1 | H25: 4 | I25: =H25*(1+汇总!$C$46) -> 4.6 | J25: 徐蔚 | K25: 46314 | L25: 46318 | M25: 新逻辑：组装动作首次入系统；组装后散件转成品库存
A26: B3 | B26: 仓储作业 ★核心 | C26: FP3-03 | D26: 组合出库单：录单 + 出库过账与台账联动 | E26: 全栈 | F26: 组合出库 列表+录单（2页） | G26: V1.1 | H26: 2 | I26: =H26*(1+汇总!$C$46) -> 2.3 | J26: 徐蔚 | K26: 46321 | L26: 46322
A27: B3 | B27: 仓储作业 ★核心 | C27: FP3-04 | D27: 退租入库验收单：按零件核对缺损并记明细 | E27: 全栈 | F27: 退租入库列表（审核弹窗） | G27: V1.1 | H27: 2 | I27: =H27*(1+汇总!$C$46) -> 2.3 | J27: 徐蔚 | K27: 46323 | L27: 46324 | M27: 由退租申请（B4）触发；退租入库加拆散去向（v2.8）
A28: B3 | B28: 仓储作业 ★核心 | C28: FP3-05 | D28: 盘点单：零件/组合双口径 + 盘盈亏过账 | E28: 全栈 | F28: 盘点 列表+录入（2页） | G28: V1.1 | H28: 3 | I28: =H28*(1+汇总!$C$46) -> 3.45 | J28: 徐蔚 | K28: 46309 | L28: 46311 | M28: V1.0→V1.1（2026-09-06 赶 10 月上线范围调整）
A29: B3 | B29: 仓储作业 ★核心 | C29: FP3-06 | D29: 库存查询：零件/组合双视角 + 库存流水 | E29: 全栈 | F29: 库存查询（含流水弹窗） | G29: V1.0 | H29: 2 | I29: =H29*(1+汇总!$C$46) -> 2.3 | J29: 徐蔚 | K29: 46280 | L29: 46281
A30: B3 | B30: 仓储作业 ★核心 | C30: （待补） | D30: 销售出库单：录单 + 出库过账（买卖线出库执行） | E30: 全栈 | F30: 销售出库列表（新建/审核弹窗） | G30: V1.0 | H30: 2 | I30: =H30*(1+汇总!$C$46) -> 2.3 | J30: 徐蔚 | K30: 46282 | L30: 46283 | M30: FP 码待补；买卖线核心出库单
A31: B3 | B31: 仓储作业 ★核心 | C31: （待补） | D31: 其他入库单：无单据来源杂项入库 | E31: 全栈 | F31: 其他入库列表（新建/审核弹窗） | G31: V1.0 | H31: 1.5 | I31: =H31*(1+汇总!$C$46) -> 1.725 | J31: 徐蔚 | K31: 46286 | L31: 46287 | M31: FP 码待补
A32: B3 | B32: 仓储作业 ★核心 | C32: （待补） | D32: 其他出库单：报废/杂项出库 | E32: 全栈 | F32: 其他出库列表（新建/审核弹窗） | G32: V1.0 | H32: 1.5 | I32: =H32*(1+汇总!$C$46) -> 1.725 | J32: 徐蔚 | K32: 46288 | L32: 46289 | M32: FP 码待补
A33: B3 | B33: 仓储作业 ★核心 | C33: （待补） | D33: 库存调拨单：库间调拨 + 过账 | E33: 全栈 | F33: 库存调拨列表（新建/审核弹窗） | G33: V1.0 | H33: 1.5 | I33: =H33*(1+汇总!$C$46) -> 1.725 | J33: 徐蔚 | K33: 46290 | L33: 46293 | M33: FP 码待补
A34: B3 | B34: 仓储作业 ★核心 | C34: （待补） | D34: 拆卸单：C→A+B 逆向、散件回库 | E34: 全栈 | F34: 拆卸管理列表（新建/审核弹窗） | G34: V1.1 | H34: 3 | I34: =H34*(1+汇总!$C$46) -> 3.45 | J34: 徐蔚 | K34: 46325 | L34: 46329 | M34: FP 码待补；组装逆向，应对日计划变更
A35: B3 | B35: 仓储作业 ★核心 | C35: （待补） | D35: 租入入库单：租入包装验收入库（L3/L4） | E35: 全栈 | F35: 租入入库列表（确认弹窗） | G35: V2.0 | H35: 1.5 | I35: =H35*(1+汇总!$C$46) -> 1.725 | J35: 徐蔚 | K35: 46337 | L35: 46338 | M35: FP 码待补；租入体系独立单据（09-04 拍板）
A36: B3 | B36: 仓储作业 ★核心 | C36: （待补） | D36: 租入归还单：归还供应商出库（L3/L4） | E36: 全栈 | F36: 租入归还列表（新建/审核弹窗） | G36: V2.0 | H36: 1.5 | I36: =H36*(1+汇总!$C$46) -> 1.725 | J36: 徐蔚 | K36: 46339 | L36: 46342 | M36: FP 码待补
A37: B4 | B37: 包装管理（租赁） | C37: FP4-01 | D37: 租出台账：页面 + 接口 | E37: 全栈 | F37: 租出台账 | G37: V1.1 | H37: 1.5 | I37: =H37*(1+汇总!$C$46) -> 1.725 | J37: 徐蔚 | K37: 46317 | L37: 46318 | M37: 资产来源标记（v2.8）
A38: B4 | B38: 包装管理（租赁） | C38: FP4-02 | D38: 在租台账：在库/在途/客户端/退租四态统计 | E38: 全栈 | F38: 在租台账（器具出租履历弹窗） | G38: V1.1 | H38: 3 | I38: =H38*(1+汇总!$C$46) -> 3.45 | J38: 徐蔚 | K38: 46321 | L38: 46323
A39: B4 | B39: 包装管理（租赁） | C39: FP4-03 | D39: 循环状态与计费：状态流转 + 按数量结算 | E39: 全栈 | F39: 在租台账（状态操作） | G39: V1.1 | H39: 3 | I39: =H39*(1+汇总!$C$46) -> 3.45 | J39: 徐蔚 | K39: 46307 | L39: 46310 | M39: #1 计费规则未确认；租金自动计费（US-14）暂不在基线
A40: B4 | B40: 包装管理（租赁） | C40: FP4-04 | D40: 丢损赔偿单：退租缺损自动生成赔偿应收 | E40: 全栈 | F40: 丢损赔偿单（审核/报废弹窗） | G40: V1.1 | H40: 2 | I40: =H40*(1+汇总!$C$46) -> 2.3 | J40: 徐蔚 | K40: 46330 | L40: 46331 | M40: 按对象转单据：客户→应收 / 运营方·供应商→应付（道远 09-04 拍板）
...
