Workbook

Sheet 功能点评估（全栈）
A1: P1-R03 工期评估表 · 功能点级（全栈口径）
A2: 口径：人日含概要设计+编码+自测；每功能点一行、不分前后端/联调（类型=全栈），功能点 FP 码对应 P1-R01 第 5.1 节。与「评估明细」二选一填写或交叉校验——汇总表「评估采用口径」决定合计采用哪套数字。黄格待填（人日按 0.5 的倍数）。排期口径：按评估人并行、任务串行，自 2026-09-02 起排，跳过双休与国庆（10/1-10/7）。
A3: WBS | B3: 模块/阶段 | C3: 功能点 | D3: 任务 | E3: 类型 | F3: 人日 | G3: 评估人 | H3: 开始时间 | I3: 结束时间 | J3: 备注（风险/依赖）
A4: A1 | B4: 需求调研与PRD | C4: — | D4: 吉客云/路凯页面与字段梳理 | E4: 调研 | F4: 2 | G4: 吕道远 | H4: 46267 | I4: 46268 | J4: 依赖 #2 #3：账号或全套截图到位后开展
A5: A1 | B5: 需求调研与PRD | C5: — | D5: 计费规则与单据流程确认 | E5: 调研 | F5: 2 | G5: 吕道远 | H5: 46269 | I5: 46272 | J5: 依赖 #1 #5：合同/报价单、单据样例
A6: A1 | B6: 需求调研与PRD | C6: — | D6: PRD 编写（按模块分册） | E6: 文档 | F6: 1 | G6: 吕道远 | H6: 46273 | I6: 46273
A7: A1 | B7: 需求调研与PRD | C7: — | D7: PRD 评审与修订 | E7: 文档 | F7: 1 | G7: 吕道远 | H7: 46274 | I7: 46274 | J7: 客户确认后方可冻结范围
A8: A2 | B8: 原型设计 | C8: — | D8: 核心流程原型（仓储作业+订单协同） | E8: 原型 | F8: 1 | G8: 吕道远 | H8: 46275 | I8: 46275
A9: A2 | B9: 原型设计 | C9: — | D9: 管理与报表原型（项目/财务/基础数据） | E9: 原型 | F9: 2 | G9: 吕道远 | H9: 46276 | I9: 46279
A10: A2 | B10: 原型设计 | C10: — | D10: 原型评审与修订 | E10: 原型 | F10: 1 | G10: 吕道远 | H10: 46280 | I10: 46280
A11: B0 | B11: 公共技术底座 | C11: — | D11: 工程脚手架与 CI/CD | E11: 全栈 | F11: 1 | G11: 陈金 | H11: 46267 | I11: 46267 | J11: 本表细化时新增，非 P1-R01 功能点，评估时确认保留
A12: B0 | B12: 公共技术底座 | C12: — | D12: 登录认证与框架权限 | E12: 全栈 | F12: 1 | G12: 陈金 | H12: 46268 | I12: 46268
A13: B0 | B13: 公共技术底座 | C13: — | D13: 通用组件（单据/列表/导入导出） | E13: 全栈 | F13: 1 | G13: 陈金 | H13: 46269 | I13: 46269
A14: B1 | B14: 基础数据 | C14: FP1-01 | D14: 项目档案：页面 + 表结构与接口 | E14: 全栈 | F14: 0.5 | G14: 陈金 | H14: 46272 | I14: 46272
A15: B1 | B15: 基础数据 | C15: FP1-02 | D15: 往来单位档案：页面 + 接口（含开票资料） | E15: 全栈 | F15: 0.5 | G15: 陈金 | H15: 46272 | I15: 46272
A16: B1 | B16: 基础数据 | C16: FP1-03 | D16: 包材档案：页面 + 接口 | E16: 全栈 | F16: 0.5 | G16: 陈金 | H16: 46273 | I16: 46273
A17: B1 | B17: 基础数据 | C17: FP1-04 | D17: 零部件档案：页面 + 接口 | E17: 全栈 | F17: 0.5 | G17: 陈金 | H17: 46273 | I17: 46273
A18: B1 | B18: 基础数据 | C18: FP1-05 | D18: 子母件 BOM：维护页 + 版本管理与配比校验 | E18: 全栈 | F18: 0.5 | G18: 陈金 | H18: 46274 | I18: 46274 | J18: 配比错误需拦截
A19: B1 | B19: 基础数据 | C19: FP1-06 | D19: 库位档案：页面 + 接口（仓/区/位三级） | E19: 全栈 | F19: 0.5 | G19: 陈金 | H19: 46274 | I19: 46274
A20: B2 | B20: 项目管理中心 | C20: FP2-01 | D20: 项目编码规则：规则引擎 + 配置页 | E20: 全栈 | F20: 0.5 | G20: 陈金 | H20: 46275 | I20: 46275
A21: B2 | B21: 项目管理中心 | C21: FP2-02 | D21: 上下游绑定：关系维护页 + 模型接口 | E21: 全栈 | F21: 0.5 | G21: 陈金 | H21: 46275 | I21: 46275
A22: B2 | B22: 项目管理中心 | C22: FP2-03 | D22: 项目看板：图表页 + 统计接口 | E22: 全栈 | F22: 1 | G22: 陈金 | H22: 46276 | I22: 46276
A23: B2 | B23: 项目管理中心 | C23: FP2-04 | D23: 明细下钻：下钻交互 + 穿透查询 | E23: 全栈 | F23: 1 | G23: 陈金 | H23: 46279 | I23: 46279
A24: B3 | B24: 仓储作业 ★核心 | C24: FP3-01 | D24: 采购入库单：录单 + 入库过账与库存更新 | E24: 全栈 | F24: 1.5 | G24: 陈金 | H24: 46280 | I24: 46281
A25: B3 | B25: 仓储作业 ★核心 | C25: FP3-02 ★新增 | D25: 小组装单：录单 + 库存转换引擎 + 拆件回退 | E25: 全栈 | F25: 1.5 | G25: 陈金 | H25: 46281 | I25: 46282 | J25: 新逻辑：组装动作首次入系统；拆件回退应对日计划频繁变更
A26: B3 | B26: 仓储作业 ★核心 | C26: FP3-03 | D26: 组合出库单：录单 + 出库过账与台账联动 | E26: 全栈 | F26: 1.5 | G26: 陈金 | H26: 46283 | I26: 46286
A27: B3 | B27: 仓储作业 ★核心 | C27: FP3-04 | D27: 退租入库验收单：录单 + 按零件缺损核对 | E27: 全栈 | F27: 1.5 | G27: 陈金 | H27: 46286 | I27: 46287
A28: B3 | B28: 仓储作业 ★核心 | C28: FP3-05 | D28: 盘点单：双口径任务页 + 盘盈亏过账 | E28: 全栈 | F28: 1.5 | G28: 陈金 | H28: 46288 | I28: 46289
A29: B3 | B29: 仓储作业 ★核心 | C29: FP3-06 | D29: 库存查询：双视角查询页 + 接口 | E29: 全栈 | F29: 1.5 | G29: 陈金 | H29: 46289 | I29: 46290
A30: B4 | B30: 租赁管理 | C30: FP4-01 | D30: 租出台账：页面 + 接口 | E30: 全栈 | F30: 0.5 | G30: 陈金 | H30: 46293 | I30: 46293
A31: B4 | B31: 租赁管理 | C31: FP4-02 | D31: 在租资产跟踪：视图 + 统计接口 | E31: 全栈 | F31: 0.5 | G31: 陈金 | H31: 46293 | I31: 46293
A32: B4 | B32: 租赁管理 | C32: FP4-03 | D32: 循环状态管理：状态机 + 操作页 | E32: 全栈 | F32: 0.5 | G32: 陈金 | H32: 46294 | I32: 46294
A33: B4 | B33: 租赁管理 | C33: FP4-04 | D33: 缺损与赔偿：登记页 + 赔偿应收联动 | E33: 全栈 | F33: 0.5 | G33: 陈金 | H33: 46294 | I33: 46294 | J33: #1 计费规则未确认；租金自动计费（US-14）暂不在基线
A34: B5 | B34: 订单协同 | C34: FP5-01 | D34: 客户下单入口：客户端下单页 + 接口校验 | E34: 全栈 | F34: 1 | G34: 陈金 | H34: 46295 | I34: 46295 | J34: 替代客户在路凯下单
A35: B5 | B35: 订单协同 | C35: FP5-02 | D35: 订单审核：工作台 + 审核流转 | E35: 全栈 | F35: 1 | G35: 陈金 | H35: 46303 | I35: 46303
A36: B5 | B36: 订单协同 | C36: FP5-03 | D36: 对路凯订单下发：下发通道 + 记录重发 | E36: 全栈 | F36: 1 | G36: 陈金 | H36: 46304 | I36: 46304 | J36: #6 对接方式待定，评估按导出/接口两档
A37: B5 | B37: 订单协同 | C37: FP5-04 | D37: 结算数据导出：数据生成 + 导出操作 | E37: 全栈 | F37: 1 | G37: 陈金 | H37: 46307 | I37: 46307 | J37: #6 结算格式待路凯方提供
A38: B6 | B38: 财务协同 | C38: FP6-01 | D38: 应收账单生成：归集规则 + 账单页 | E38: 全栈 | F38: 1 | G38: 陈金 | H38: 46308 | I38: 46308
A39: B6 | B39: 财务协同 | C39: FP6-02 | D39: 开票登记：登记页 + 应收关联 | E39: 全栈 | F39: 1 | G39: 陈金 | H39: 46309 | I39: 46309 | J39: 依赖 #8 开票主体信息
A40: B6 | B40: 财务协同 | C40: FP6-03 | D40: 回款登记：登记页 + 到账关联 | E40: 全栈 | F40: 1 | G40: 陈金 | H40: 46310 | I40: 46310
...

Sheet 汇总
A1: 汇总与折算（公式驱动，唯一维护处）
A3: WBS | B3: 模块/阶段 | C3: 子任务数 | D3: 人日小计·子任务级 | E3: 人日小计·全栈级 | F3: 关键风险/依赖
A4: A1 | B4: 需求调研与PRD | C4: =COUNTIF('评估明细-待激活'!$A:$A,$A4) | D4: =SUMIF('评估明细-待激活'!$A:$A,$A4,'评估明细-待激活'!$F:$F) | E4: =SUMIF('功能点评估（全栈）'!$A:$A,$A4,'功能点评估（全栈）'!$F:$F) | F4: #2 #3 材料未齐即启动，PRD 有返工风险
A5: A2 | B5: 原型设计 | C5: =COUNTIF('评估明细-待激活'!$A:$A,$A5) | D5: =SUMIF('评估明细-待激活'!$A:$A,$A5,'评估明细-待激活'!$F:$F) | E5: =SUMIF('功能点评估（全栈）'!$A:$A,$A5,'功能点评估（全栈）'!$F:$F)
A6: B0 | B6: 公共技术底座 | C6: =COUNTIF('评估明细-待激活'!$A:$A,$A6) | D6: =SUMIF('评估明细-待激活'!$A:$A,$A6,'评估明细-待激活'!$F:$F) | E6: =SUMIF('功能点评估（全栈）'!$A:$A,$A6,'功能点评估（全栈）'!$F:$F) | F6: 细化新增行，评估时确认是否保留
A7: B1 | B7: 基础数据 | C7: =COUNTIF('评估明细-待激活'!$A:$A,$A7) | D7: =SUMIF('评估明细-待激活'!$A:$A,$A7,'评估明细-待激活'!$F:$F) | E7: =SUMIF('功能点评估（全栈）'!$A:$A,$A7,'功能点评估（全栈）'!$F:$F)
A8: B2 | B8: 项目管理中心 | C8: =COUNTIF('评估明细-待激活'!$A:$A,$A8) | D8: =SUMIF('评估明细-待激活'!$A:$A,$A8,'评估明细-待激活'!$F:$F) | E8: =SUMIF('功能点评估（全栈）'!$A:$A,$A8,'功能点评估（全栈）'!$F:$F)
A9: B3 | B9: 仓储作业 ★核心 | C9: =COUNTIF('评估明细-待激活'!$A:$A,$A9) | D9: =SUMIF('评估明细-待激活'!$A:$A,$A9,'评估明细-待激活'!$F:$F) | E9: =SUMIF('功能点评估（全栈）'!$A:$A,$A9,'功能点评估（全栈）'!$F:$F) | F9: 小组装为全新逻辑，PRD 冻结前估算偏差大
A10: B4 | B10: 租赁管理 | C10: =COUNTIF('评估明细-待激活'!$A:$A,$A10) | D10: =SUMIF('评估明细-待激活'!$A:$A,$A10,'评估明细-待激活'!$F:$F) | E10: =SUMIF('功能点评估（全栈）'!$A:$A,$A10,'功能点评估（全栈）'!$F:$F) | F10: #1 计费规则未确认（US-14 暂不在基线）
A11: B5 | B11: 订单协同 | C11: =COUNTIF('评估明细-待激活'!$A:$A,$A11) | D11: =SUMIF('评估明细-待激活'!$A:$A,$A11,'评估明细-待激活'!$F:$F) | E11: =SUMIF('功能点评估（全栈）'!$A:$A,$A11,'功能点评估（全栈）'!$F:$F) | F11: #6 路凯对接方式待定
A12: B6 | B12: 财务协同 | C12: =COUNTIF('评估明细-待激活'!$A:$A,$A12) | D12: =SUMIF('评估明细-待激活'!$A:$A,$A12,'评估明细-待激活'!$F:$F) | E12: =SUMIF('功能点评估（全栈）'!$A:$A,$A12,'功能点评估（全栈）'!$F:$F) | F12: #5 单据/水单样例、#8 开票主体待提供
A13: B7 | B13: 系统管理 | C13: =COUNTIF('评估明细-待激活'!$A:$A,$A13) | D13: =SUMIF('评估明细-待激活'!$A:$A,$A13,'评估明细-待激活'!$F:$F) | E13: =SUMIF('功能点评估（全栈）'!$A:$A,$A13,'功能点评估（全栈）'!$F:$F)
A14: C1 | B14: 测试 | C14: =COUNTIF('评估明细-待激活'!$A:$A,$A14) | D14: =SUMIF('评估明细-待激活'!$A:$A,$A14,'评估明细-待激活'!$F:$F) | E14: =SUMIF('功能点评估（全栈）'!$A:$A,$A14,'功能点评估（全栈）'!$F:$F)
A15: C2 | B15: 数据迁移 | C15: =COUNTIF('评估明细-待激活'!$A:$A,$A15) | D15: =SUMIF('评估明细-待激活'!$A:$A,$A15,'评估明细-待激活'!$F:$F) | E15: =SUMIF('功能点评估（全栈）'!$A:$A,$A15,'功能点评估（全栈）'!$F:$F) | F15: #4 主数据清单与格式待提供
A16: C3 | B16: 上线部署 | C16: =COUNTIF('评估明细-待激活'!$A:$A,$A16) | D16: =SUMIF('评估明细-待激活'!$A:$A,$A16,'评估明细-待激活'!$F:$F) | E16: =SUMIF('功能点评估（全栈）'!$A:$A,$A16,'功能点评估（全栈）'!$F:$F)
B17: 合计人日 | D17: =SUM(D4:D16) | E17: =SUM(E4:E16)
A19: 参数与折算
A20: 评估采用口径 | C20: 全栈 | D20: 子任务级 / 全栈级 二选一，合计与折算随之切换
A21: 缓冲比例 | D21: 建议 15%~20%，覆盖联调与管理裕度
A22: 投入人数 | D22: 对应 P1-R01 第八节 #10，确认后填入
A23: 每月工作日 | C23: 21 | D23: 人月折算基准
A24: 采用合计（人日） | C24: =IF(IF($C$20="全栈",$E$17,$D$17)=0,"",IF($C$20="全栈",$E$17,$D$17))
A25: 含缓冲合计（人日） | C25: =IF(OR($C$21="",IF($C$20="全栈",$E$17,$D$17)=0),"",IF($C$20="全栈",$E$17,$D$17)*(1+$C$21))
A26: 日历工期（月） | C26: =IF(OR($C$21="",$C$22="",$C$22=0,$C$24=0),"",$C$24/($C$23*$C$22))
A27: 日历工期（周） | C27: =IF(OR($C$21="",$C$22="",$C$22=0,$C$24=0),"",$C$24/($C$23*$C$22)*4.33)

Sheet 评估明细-待激活
A1: P1-R03 工期评估表 · 子任务级明细
A2: 口径：人日含概要设计+编码+自测；每功能点按前端/后端/联调拆行，功能点 FP 码对应 P1-R01 第 5.1 节。与「功能点评估（全栈）」二选一填写或交叉校验——汇总表「评估采用口径」决定合计采用哪套数字。黄格待填（人日按 0.5 的倍数），灰格公式勿动。
A3: WBS | B3: 模块/阶段 | C3: 功能点 | D3: 任务 | E3: 类型 | F3: 人日 | G3: 评估人 | H3: 备注（风险/依赖）
A4: A1 | B4: 需求调研与PRD | C4: — | D4: 吉客云/路凯页面与字段梳理 | E4: 调研 | H4: 依赖 #2 #3：账号或全套截图到位后开展
A5: A1 | B5: 需求调研与PRD | C5: — | D5: 计费规则与单据流程确认 | E5: 调研 | H5: 依赖 #1 #5：合同/报价单、单据样例
A6: A1 | B6: 需求调研与PRD | C6: — | D6: PRD 编写（按模块分册） | E6: 文档
A7: A1 | B7: 需求调研与PRD | C7: — | D7: PRD 评审与修订 | E7: 文档 | H7: 客户确认后方可冻结范围
A8: A2 | B8: 原型设计 | C8: — | D8: 核心流程原型（仓储作业+订单协同） | E8: 原型
A9: A2 | B9: 原型设计 | C9: — | D9: 管理与报表原型（项目/财务/基础数据） | E9: 原型
A10: A2 | B10: 原型设计 | C10: — | D10: 原型评审与修订 | E10: 原型
A11: B0 | B11: 公共技术底座 | C11: — | D11: 工程脚手架与 CI/CD | E11: 后端 | H11: 本表细化时新增，非 P1-R01 功能点，评估时确认保留
A12: B0 | B12: 公共技术底座 | C12: — | D12: 登录认证与框架权限 | E12: 后端
A13: B0 | B13: 公共技术底座 | C13: — | D13: 通用组件（单据/列表/导入导出） | E13: 前端
A14: B1 | B14: 基础数据 | C14: FP1-01 | D14: 项目档案列表/表单页 | E14: 前端
A15: B1 | B15: 基础数据 | C15: FP1-01 | D15: 项目档案表结构与接口 | E15: 后端
A16: B1 | B16: 基础数据 | C16: FP1-02 | D16: 往来单位列表/表单页（客户/供应商/运营方） | E16: 前端
A17: B1 | B17: 基础数据 | C17: FP1-02 | D17: 往来单位表结构与接口（含开票资料） | E17: 后端
A18: B1 | B18: 基础数据 | C18: FP1-03 | D18: 包材档案页面（规格/单位/资产标记） | E18: 前端
A19: B1 | B19: 基础数据 | C19: FP1-03 | D19: 包材表结构与接口 | E19: 后端
A20: B1 | B20: 基础数据 | C20: FP1-04 | D20: 零部件档案页面（供应商来源/共用标记） | E20: 前端
A21: B1 | B21: 基础数据 | C21: FP1-04 | D21: 零部件表结构与接口 | E21: 后端
A22: B1 | B22: 基础数据 | C22: FP1-05 | D22: BOM 维护页（母件-子件配比） | E22: 前端
A23: B1 | B23: 基础数据 | C23: FP1-05 | D23: BOM 版本管理与配比校验逻辑 | E23: 后端 | H23: 配比错误需拦截
A24: B1 | B24: 基础数据 | C24: FP1-06 | D24: 库位档案页面（仓/区/位三级） | E24: 前端
A25: B1 | B25: 基础数据 | C25: FP1-06 | D25: 库位表结构与接口 | E25: 后端
A26: B2 | B26: 项目管理中心 | C26: FP2-01 | D26: 项目编码规则引擎（可配置） | E26: 后端
A27: B2 | B27: 项目管理中心 | C27: FP2-01 | D27: 编码规则配置页 | E27: 前端
A28: B2 | B28: 项目管理中心 | C28: FP2-02 | D28: 上下游关系维护页（项目↔客户↔运营方↔供应商） | E28: 前端
A29: B2 | B29: 项目管理中心 | C29: FP2-02 | D29: 关系模型与接口 | E29: 后端
A30: B2 | B30: 项目管理中心 | C30: FP2-03 | D30: 项目看板页（出入库/营收/盈利图表） | E30: 前端
A31: B2 | B31: 项目管理中心 | C31: FP2-03 | D31: 看板统计接口 | E31: 后端
A32: B2 | B32: 项目管理中心 | C32: FP2-04 | D32: 看板明细下钻交互 | E32: 前端
A33: B2 | B33: 项目管理中心 | C33: FP2-04 | D33: 穿透查询接口（看板→单据） | E33: 后端
A34: B3 | B34: 仓储作业 ★核心 | C34: FP3-01 | D34: 采购入库单录单页（按零件、以托为单位） | E34: 前端
A35: B3 | B35: 仓储作业 ★核心 | C35: FP3-01 | D35: 入库过账与库存更新逻辑 | E35: 后端
A36: B3 | B36: 仓储作业 ★核心 | C36: FP3-02 ★新增 | D36: 小组装单录单页（运营方/时间/数量） | E36: 前端 | H36: 新逻辑：组装动作首次入系统
A37: B3 | B37: 仓储作业 ★核心 | C37: FP3-02 ★新增 | D37: 组装库存转换引擎（子件扣减→母件入库） | E37: 后端 | H37: 零件/组合双视角库存核心，需 PRD 细化
A38: B3 | B38: 仓储作业 ★核心 | C38: FP3-02 ★新增 | D38: 拆件回退（日计划变更场景） | E38: 后端 | H38: 客户改单频繁，需支持逆向
A39: B3 | B39: 仓储作业 ★核心 | C39: FP3-03 | D39: 组合出库单录单页（一箱一件、关联订单） | E39: 前端
A40: B3 | B40: 仓储作业 ★核心 | C40: FP3-03 | D40: 出库过账与在租台账联动 | E40: 后端
...
